1602489600086
1602576009746
1602662400104
1602668043330
1602748809391
1602835200088
1602921600077
1603008000065
1603094409263
1603180800108
1603267200074
1603353600069
1603440000092
1603526400087
1603612800067
1603699200072
1603785600091
1603872000089
1603958400088
1604044800073
1604047228977
1604047418293
1604056432278
1604131200094
1604217600068
1604304000100
1604390400104
1604476800069
1604563200106
1604649600072
1604736000105
1604822400112
1604908800086
1604995200068
1605081600072
1605168000087
1605254400091
1605340800082
1605427200111
1605513600109
1605600000104
1605686400072
1605772800110
Traceback (most recent call last):
  File "/home/pi/Documents/Github/cocoa-getinfo/webupdate_notify.py", line 85, in <module>

    cocoa_analysis.main_process()
  File "/home/pi/Documents/Github/cocoa-getinfo/cocoa_analysis.py", line 23, in main_process

    cocoa_wordsearch_datapush.search_and_push(1)
  File "/home/pi/Documents/Github/cocoa-getinfo/sub_sys/cocoa_wordsearch_datapush.py", line 104, in search_and_push

    found2 = match2[0]
IndexError: list index out of range

1605786831443
Traceback (most recent call last):
  File "/home/pi/Documents/Github/cocoa-getinfo/webupdate_notify.py", line 85, in <module>

    cocoa_analysis.main_process()
  File "/home/pi/Documents/Github/cocoa-getinfo/cocoa_analysis.py", line 23, in main_process
    cocoa_wordsearch_datapush.search_and_push(1)
  File "/home/pi/Documents/Github/cocoa-getinfo/sub_sys/cocoa_wordsearch_datapush.py", line 104, in search_and_push
    found2 = match2[0]
IndexError: list index out of range

1605859209859
1605945600112
1606032000105
1606118400071
1606204810020
Traceback (most recent call last):
  File "/home/pi/Documents/Github/cocoa-getinfo/webupdate_notify.py", line 85, in <module>

    cocoa_analysis.main_process()
  File "/home/pi/Documents/Github/cocoa-getinfo/cocoa_analysis.py", line 23, in main_process

    cocoa_wordsearch_datapush.search_and_push(1)

  File "/home/pi/Documents/Github/cocoa-getinfo/sub_sys/cocoa_wordsearch_datapush.py", line 211, in search_and_push

    f.writelines(dx1)
TypeError: 'int' object is not iterable

1606205211256
Traceback (most recent call last):
  File "/home/pi/Documents/Github/cocoa-getinfo/webupdate_notify.py", line 85, in <module>

    cocoa_analysis.main_process()
  File "/home/pi/Documents/Github/cocoa-getinfo/cocoa_analysis.py", line 23, in main_process
    cocoa_wordsearch_datapush.search_and_push(1)
  File "/home/pi/Documents/Github/cocoa-getinfo/sub_sys/cocoa_wordsearch_datapush.py", line 211, in search_and_push

    f.writelines(dx1)
TypeError: 'int' object is not iterable

1606209107949
Traceback (most recent call last):
  File "/home/pi/Documents/Github/cocoa-getinfo/webupdate_notify.py", line 85, in <module>

    cocoa_analysis.main_process()
  File "/home/pi/Documents/Github/cocoa-getinfo/cocoa_analysis.py", line 23, in main_process
    cocoa_wordsearch_datapush.search_and_push(1)
  File "/home/pi/Documents/Github/cocoa-getinfo/sub_sys/cocoa_wordsearch_datapush.py", line 169, in search_and_push

    dx1 = ffound - yy1
TypeError: unsupported operand type(s) for -: 'int' and 'str'

1606209289690
Traceback (most recent call last):
  File "/home/pi/Documents/Github/cocoa-getinfo/webupdate_notify.py", line 85, in <module>
    cocoa_analysis.main_process()
  File "/home/pi/Documents/Github/cocoa-getinfo/cocoa_analysis.py", line 23, in main_process

    cocoa_wordsearch_datapush.search_and_push(1)
  File "/home/pi/Documents/Github/cocoa-getinfo/sub_sys/cocoa_wordsearch_datapush.py", line 213, in search_and_push

    f.writelines(dx1)
TypeError: 'int' object is not iterable

1606209891500
Traceback (most recent call last):
  File "/home/pi/Documents/Github/cocoa-getinfo/webupdate_notify.py", line 85, in <module>

    cocoa_analysis.main_process()
  File "/home/pi/Documents/Github/cocoa-getinfo/cocoa_analysis.py", line 23, in main_process
    cocoa_wordsearch_datapush.search_and_push(1)
  File "/home/pi/Documents/Github/cocoa-getinfo/sub_sys/cocoa_wordsearch_datapush.py", line 215, in search_and_push

    f.writelines(dx1)
TypeError: 'int' object is not iterable

1606210421674
Traceback (most recent call last):
  File "/home/pi/Documents/Github/cocoa-getinfo/webupdate_notify.py", line 85, in <module>

    cocoa_analysis.main_process()
  File "/home/pi/Documents/Github/cocoa-getinfo/cocoa_analysis.py", line 23, in main_process
    cocoa_wordsearch_datapush.search_and_push(1)
  File "/home/pi/Documents/Github/cocoa-getinfo/sub_sys/cocoa_wordsearch_datapush.py", line 171, in search_and_push
    dx1 = ffound - int(first_line)
NameError: name 'first_line' is not defined

1606210566093
1606210985985
1606291200079
1606377600090
1606464000101
1606550400091
1606636800082
1606723200084
1606809600098
1606896000081
1606982400891
1606984053592
1607068800077
1607155200102
1607241600076
1607328000077
1607342635284
1607414400073
1607500808523
1607587200115
1607673600081
1607760000081
1607846400080
1607932800082
Traceback (most recent call last):
  File "/home/pi/Documents/Github/cocoa-getinfo/webupdate_notify.py", line 85, in <module>

    cocoa_analysis.main_process()
  File "/home/pi/Documents/Github/cocoa-getinfo/cocoa_analysis.py", line 23, in main_process
    cocoa_wordsearch_datapush.search_and_push(1)
  File "/home/pi/Documents/Github/cocoa-getinfo/sub_sys/cocoa_wordsearch_datapush.py", line 121, in search_and_push

    if found == 'N/A' and found2 == 'N/A':  # 追加処理のみ更新無
UnboundLocalError: local variable 'found' referenced before assignment

1608019200121
1608105600100
Traceback (most recent call last):
  File "/home/pi/Documents/Github/cocoa-getinfo/webupdate_notify.py", line 85, in <module>

    cocoa_analysis.main_process()
  File "/home/pi/Documents/Github/cocoa-getinfo/cocoa_analysis.py", line 23, in main_process
    cocoa_wordsearch_datapush.search_and_push(1)
  File "/home/pi/Documents/Github/cocoa-getinfo/sub_sys/cocoa_wordsearch_datapush.py", line 121, in search_and_push
    if found == 'N/A' and found2 == 'N/A':  # 追加処理のみ更新無
UnboundLocalError: local variable 'found' referenced before assignment

1608112993765
Traceback (most recent call last):
  File "/home/pi/Documents/Github/cocoa-getinfo/webupdate_notify.py", line 85, in <module>

    cocoa_analysis.main_process()
  File "/home/pi/Documents/Github/cocoa-getinfo/cocoa_analysis.py", line 23, in main_process
    cocoa_wordsearch_datapush.search_and_push(1)
  File "/home/pi/Documents/Github/cocoa-getinfo/sub_sys/cocoa_wordsearch_datapush.py", line 121, in search_and_push
    if found == 'N/A' and found2 == 'N/A':  # 追加処理のみ更新無

UnboundLocalError: local variable 'found' referenced before assignment

Traceback (most recent call last):
  File "/home/pi/Documents/Github/cocoa-getinfo/webupdate_notify.py", line 85, in <module>
    cocoa_analysis.main_process()
  File "/home/pi/Documents/Github/cocoa-getinfo/cocoa_analysis.py", line 23, in main_process
    cocoa_wordsearch_datapush.search_and_push(1)
  File "/home/pi/Documents/Github/cocoa-getinfo/sub_sys/cocoa_wordsearch_datapush.py", line 121, in search_and_push
    if found == 'N/A' and found2 == 'N/A':  # 追加処理のみ更新無
UnboundLocalError: local variable 'found' referenced before assignment

Traceback (most recent call last):
  File "/home/pi/Documents/Github/cocoa-getinfo/webupdate_notify.py", line 85, in <module>
    cocoa_analysis.main_process()
  File "/home/pi/Documents/Github/cocoa-getinfo/cocoa_analysis.py", line 23, in main_process

    cocoa_wordsearch_datapush.search_and_push(1)
  File "/home/pi/Documents/Github/cocoa-getinfo/sub_sys/cocoa_wordsearch_datapush.py", line 121, in search_and_push
    if found == 'N/A' and found2 == 'N/A':  # 追加処理のみ更新無
UnboundLocalError: local variable 'found' referenced before assignment

Traceback (most recent call last):
  File "/home/pi/Documents/Github/cocoa-getinfo/webupdate_notify.py", line 85, in <module>

    cocoa_analysis.main_process()
  File "/home/pi/Documents/Github/cocoa-getinfo/cocoa_analysis.py", line 23, in main_process
    cocoa_wordsearch_datapush.search_and_push(1)
  File "/home/pi/Documents/Github/cocoa-getinfo/sub_sys/cocoa_wordsearch_datapush.py", line 121, in search_and_push
    if found == 'N/A' and found2 == 'N/A':  # 追加処理のみ更新無
UnboundLocalError: local variable 'found' referenced before assignment

Traceback (most recent call last):
  File "/home/pi/Documents/Github/cocoa-getinfo/webupdate_notify.py", line 85, in <module>

    cocoa_analysis.main_process()
  File "/home/pi/Documents/Github/cocoa-getinfo/cocoa_analysis.py", line 23, in main_process
    cocoa_wordsearch_datapush.search_and_push(1)
  File "/home/pi/Documents/Github/cocoa-getinfo/sub_sys/cocoa_wordsearch_datapush.py", line 121, in search_and_push
    if found == 'N/A' and found2 == 'N/A':  # 追加処理のみ更新無
UnboundLocalError: local variable 'found' referenced before assignment

Traceback (most recent call last):
  File "/home/pi/Documents/Github/cocoa-getinfo/webupdate_notify.py", line 85, in <module>

    cocoa_analysis.main_process()
  File "/home/pi/Documents/Github/cocoa-getinfo/cocoa_analysis.py", line 20, in main_process
    cocoa_pyocr.py_ocr()
  File "/home/pi/Documents/Github/cocoa-getinfo/sub_sys/cocoa_pyocr.py", line 37, in py_ocr
    img = img.convert('RGB')
UnboundLocalError: local variable 'img' referenced before assignment

1608116891450
1608192000085
1608278400098
1608364800111
1608451200094
1608537600074
1608624000071
1608710400077
1608796800086
1608883200096
1608969600072
1609056000075
1609142400082
1609228800090
1609315200110
1609401600117
1609488000097
1609574400074
1609660809847
1609747200101
1609833600108
1609920000102
1610006400082
1610092800068
1610179200073
1610265600082
1610352000096
1610438400069
1610524800093
1610611200068
1610697600085
1610784000093
1610870400080
1610956800098
1611043200072
1611129600090
1611216000078
Traceback (most recent call last):
  File "/home/pi/.local/lib/python3.5/site-packages/urllib3/connectionpool.py", line 426, in _make_request

    six.raise_from(e, None)

  File "<string>", line 3, in raise_from
  File "/home/pi/.local/lib/python3.5/site-packages/urllib3/connectionpool.py", line 421, in _make_request

    httplib_response = conn.getresponse()
  File "/usr/lib/python3.5/http/client.py", line 1236, in getresponse

    response.begin()
  File "/usr/lib/python3.5/http/client.py", line 307, in begin

    version, status, reason = self._read_status()
  File "/usr/lib/python3.5/http/client.py", line 268, in _read_status

    line = str(self.fp.readline(_MAXLINE + 1), "iso-8859-1")
  File "/usr/lib/python3.5/socket.py", line 576, in readinto

    return self._sock.recv_into(b)
  File "/usr/lib/python3.5/ssl.py", line 937, in recv_into

    return self.read(nbytes, buffer)
  File "/usr/lib/python3.5/ssl.py", line 799, in read

    return self._sslobj.read(len, buffer)
  File "/usr/lib/python3.5/ssl.py", line 583, in read

    v = self._sslobj.read(len, buffer)

socket.timeout: The read operation timed out

During handling of the above exception, another exception occurred:

Traceback (most recent call last):
  File "/home/pi/.local/lib/python3.5/site-packages/requests/adapters.py", line 449, in send

    timeout=timeout
  File "/home/pi/.local/lib/python3.5/site-packages/urllib3/connectionpool.py", line 727, in urlopen

    method, url, error=e, _pool=self, _stacktrace=sys.exc_info()[2]
  File "/home/pi/.local/lib/python3.5/site-packages/urllib3/util/retry.py", line 403, in increment

    raise six.reraise(type(error), error, _stacktrace)
  File "/home/pi/.local/lib/python3.5/site-packages/urllib3/packages/six.py", line 735, in reraise

    raise value
  File "/home/pi/.local/lib/python3.5/site-packages/urllib3/connectionpool.py", line 677, in urlopen

    chunked=chunked,
  File "/home/pi/.local/lib/python3.5/site-packages/urllib3/connectionpool.py", line 428, in _make_request

    self._raise_timeout(err=e, url=url, timeout_value=read_timeout)
  File "/home/pi/.local/lib/python3.5/site-packages/urllib3/connectionpool.py", line 336, in _raise_timeout

    self, url, "Read timed out. (read timeout=%s)" % timeout_value
urllib3.exceptions.ReadTimeoutError: HTTPSConnectionPool(host='sheets.googleapis.com', port=443): Read timed out. (read timeout=120)

During handling of the above exception, another exception occurred:

Traceback (most recent call last):
  File "/home/pi/Documents/Github/cocoa-getinfo/webupdate_notify.py", line 85, in <module>

    cocoa_analysis.main_process()
  File "/home/pi/Documents/Github/cocoa-getinfo/cocoa_analysis.py", line 34, in main_process
    df = cocoa_gspread_pull.sheet_pull()

  File "/home/pi/Documents/Github/cocoa-getinfo/sub_sys/cocoa_gspread_pull.py", line 57, in sheet_pull
    days_list = ws.col_values(1)
  File "/home/pi/.local/lib/python3.5/site-packages/gspread/models.py", line 831, in col_values

    'majorDimension': 'COLUMNS',
  File "/home/pi/.local/lib/python3.5/site-packages/gspread/models.py", line 191, in values_get

    r = self.client.request('get', url, params=params)
  File "/home/pi/.local/lib/python3.5/site-packages/gspread/client.py", line 67, in request
    headers=headers,
  File "/home/pi/.local/lib/python3.5/site-packages/requests/sessions.py", line 543, in get

    return self.request('GET', url, **kwargs)
  File "/home/pi/.local/lib/python3.5/site-packages/google/auth/transport/requests.py", line 470, in request

    **kwargs
  File "/home/pi/.local/lib/python3.5/site-packages/requests/sessions.py", line 530, in request

    resp = self.send(prep, **send_kwargs)
  File "/home/pi/.local/lib/python3.5/site-packages/requests/sessions.py", line 643, in send

    r = adapter.send(request, **kwargs)
  File "/home/pi/.local/lib/python3.5/site-packages/requests/adapters.py", line 529, in send

    raise ReadTimeout(e, request=request)

requests.exceptions.ReadTimeout: HTTPSConnectionPool(host='sheets.googleapis.com', port=443): Read timed out. (read timeout=120)

1611302400109
1611388800104
1611475200081
1611561600079
1611648009479
1611734400105
1611820800081
1611907200081
1611993600081
1612080000075
1612166400084
1612252800093
1612339200089
1612425600095
1612512000103
1612598400097
1612684800084
1612771200089
1612857600094
1612944000074
1613030400089
1613116800080
1613203200073
1613289600105
1613376000093
1613462400073
1613548800077
1613635200104
1613721600080
1613808000070
1613894400069
1613980800083
python3: can't open file '/home/pi/Documents/Github/cocoa_analysis_holiday.py': [Errno 2] No such file or directory

1614067200085
1614153600091
1614240000077
1614326400093
Traceback (most recent call last):
  File "/home/pi/Documents/Github/cocoa-getinfo/webupdate_notify.py", line 85, in <module>
    cocoa_analysis.main_process()

  File "/home/pi/Documents/Github/cocoa-getinfo/cocoa_analysis.py", line 23, in main_process
    cocoa_wordsearch_datapush.search_and_push(1)
  File "/home/pi/Documents/Github/cocoa-getinfo/sub_sys/cocoa_wordsearch_datapush.py", line 153, in search_and_push
    print("陽性者登録数 : " + found2 + "\n")
UnboundLocalError: local variable 'found2' referenced before assignment

Traceback (most recent call last):
  File "/home/pi/Documents/Github/cocoa-getinfo/webupdate_notify.py", line 85, in <module>

    cocoa_analysis.main_process()
  File "/home/pi/Documents/Github/cocoa-getinfo/cocoa_analysis.py", line 23, in main_process
    cocoa_wordsearch_datapush.search_and_push(1)
  File "/home/pi/Documents/Github/cocoa-getinfo/sub_sys/cocoa_wordsearch_datapush.py", line 121, in search_and_push
    if found == 'N/A' and found2 == 'N/A':  # 追加処理のみ更新無
UnboundLocalError: local variable 'found' referenced before assignment

Traceback (most recent call last):
  File "/home/pi/Documents/Github/cocoa-getinfo/webupdate_notify.py", line 85, in <module>
    cocoa_analysis.main_process()
  File "/home/pi/Documents/Github/cocoa-getinfo/cocoa_analysis.py", line 23, in main_process

    cocoa_wordsearch_datapush.search_and_push(1)
  File "/home/pi/Documents/Github/cocoa-getinfo/sub_sys/cocoa_wordsearch_datapush.py", line 153, in search_and_push
    print("陽性者登録数 : " + found2 + "\n")
UnboundLocalError: local variable 'found2' referenced before assignment

Traceback (most recent call last):
  File "/home/pi/Documents/Github/cocoa-getinfo/webupdate_notify.py", line 85, in <module>

    cocoa_analysis.main_process()
  File "/home/pi/Documents/Github/cocoa-getinfo/cocoa_analysis.py", line 23, in main_process
    cocoa_wordsearch_datapush.search_and_push(1)
  File "/home/pi/Documents/Github/cocoa-getinfo/sub_sys/cocoa_wordsearch_datapush.py", line 153, in search_and_push
    print("陽性者登録数 : " + found2 + "\n")
UnboundLocalError: local variable 'found2' referenced before assignment

Traceback (most recent call last):
  File "/home/pi/Documents/Github/cocoa-getinfo/webupdate_notify.py", line 85, in <module>

    cocoa_analysis.main_process()
  File "/home/pi/Documents/Github/cocoa-getinfo/cocoa_analysis.py", line 20, in main_process
    cocoa_pyocr.py_ocr()
  File "/home/pi/Documents/Github/cocoa-getinfo/sub_sys/cocoa_pyocr.py", line 67, in py_ocr
    text = tool.image_to_string(img_rgb, lang="jpn", builder=builder)
NameError: name 'img_rgb' is not defined

Traceback (most recent call last):
  File "/home/pi/Documents/Github/cocoa-getinfo/webupdate_notify.py", line 85, in <module>
    cocoa_analysis.main_process()
  File "/home/pi/Documents/Github/cocoa-getinfo/cocoa_analysis.py", line 23, in main_process
    cocoa_wordsearch_datapush.search_and_push(1)
  File "/home/pi/Documents/Github/cocoa-getinfo/sub_sys/cocoa_wordsearch_datapush.py", line 121, in search_and_push
    if found == 'N/A' and found2 == 'N/A':  # 追加処理のみ更新無
UnboundLocalError: local variable 'found' referenced before assignment

Traceback (most recent call last):
  File "/home/pi/Documents/Github/cocoa-getinfo/webupdate_notify.py", line 85, in <module>
    cocoa_analysis.main_process()
  File "/home/pi/Documents/Github/cocoa-getinfo/cocoa_analysis.py", line 23, in main_process
    cocoa_wordsearch_datapush.search_and_push(1)
  File "/home/pi/Documents/Github/cocoa-getinfo/sub_sys/cocoa_wordsearch_datapush.py", line 153, in search_and_push
    print("陽性者登録数 : " + found2 + "\n")
UnboundLocalError: local variable 'found2' referenced before assignment

1614412800077
1614499200083
1614585600099
Traceback (most recent call last):
  File "/home/pi/Documents/Github/cocoa-getinfo/webupdate_notify.py", line 85, in <module>
    cocoa_analysis.main_process()
  File "/home/pi/Documents/Github/cocoa-getinfo/cocoa_analysis.py", line 23, in main_process

    cocoa_wordsearch_datapush.search_and_push(1)
  File "/home/pi/Documents/Github/cocoa-getinfo/sub_sys/cocoa_wordsearch_datapush.py", line 121, in search_and_push

    if found == 'N/A' and found2 == 'N/A':  # 追加処理のみ更新無
UnboundLocalError: local variable 'found2' referenced before assignment

Traceback (most recent call last):
  File "/home/pi/Documents/Github/cocoa-getinfo/webupdate_notify.py", line 85, in <module>

    cocoa_analysis.main_process()
  File "/home/pi/Documents/Github/cocoa-getinfo/cocoa_analysis.py", line 23, in main_process
    cocoa_wordsearch_datapush.search_and_push(1)
  File "/home/pi/Documents/Github/cocoa-getinfo/sub_sys/cocoa_wordsearch_datapush.py", line 121, in search_and_push
    if found == 'N/A' and found2 == 'N/A':  # 追加処理のみ更新無
UnboundLocalError: local variable 'found' referenced before assignment

Traceback (most recent call last):
  File "/home/pi/Documents/Github/cocoa-getinfo/webupdate_notify.py", line 85, in <module>

    cocoa_analysis.main_process()
  File "/home/pi/Documents/Github/cocoa-getinfo/cocoa_analysis.py", line 23, in main_process
    cocoa_wordsearch_datapush.search_and_push(1)
  File "/home/pi/Documents/Github/cocoa-getinfo/sub_sys/cocoa_wordsearch_datapush.py", line 121, in search_and_push
    if found == 'N/A' and found2 == 'N/A':  # 追加処理のみ更新無
UnboundLocalError: local variable 'found' referenced before assignment

Traceback (most recent call last):
  File "/home/pi/Documents/Github/cocoa-getinfo/webupdate_notify.py", line 85, in <module>
    cocoa_analysis.main_process()
  File "/home/pi/Documents/Github/cocoa-getinfo/cocoa_analysis.py", line 23, in main_process
    cocoa_wordsearch_datapush.search_and_push(1)
  File "/home/pi/Documents/Github/cocoa-getinfo/sub_sys/cocoa_wordsearch_datapush.py", line 153, in search_and_push
    print("陽性者登録数 : " + found2 + "\n")
UnboundLocalError: local variable 'found2' referenced before assignment

Traceback (most recent call last):
  File "/home/pi/Documents/Github/cocoa-getinfo/webupdate_notify.py", line 85, in <module>

    cocoa_analysis.main_process()
  File "/home/pi/Documents/Github/cocoa-getinfo/cocoa_analysis.py", line 23, in main_process
    cocoa_wordsearch_datapush.search_and_push(1)
  File "/home/pi/Documents/Github/cocoa-getinfo/sub_sys/cocoa_wordsearch_datapush.py", line 153, in search_and_push
    print("陽性者登録数 : " + found2 + "\n")
UnboundLocalError: local variable 'found2' referenced before assignment

1614672000073
Traceback (most recent call last):
  File "/home/pi/Documents/Github/cocoa-getinfo/webupdate_notify.py", line 85, in <module>

    cocoa_analysis.main_process()
  File "/home/pi/Documents/Github/cocoa-getinfo/cocoa_analysis.py", line 23, in main_process
    cocoa_wordsearch_datapush.search_and_push(1)
  File "/home/pi/Documents/Github/cocoa-getinfo/sub_sys/cocoa_wordsearch_datapush.py", line 153, in search_and_push
    print("陽性者登録数 : " + found2 + "\n")
UnboundLocalError: local variable 'found2' referenced before assignment

1614758400112
1614844800102
1614931200077
Traceback (most recent call last):
  File "/home/pi/Documents/Github/cocoa-getinfo/webupdate_notify.py", line 2, in <module>

    import requests
ModuleNotFoundError: No module named 'requests'

Traceback (most recent call last):
  File "/home/pi/Documents/Github/cocoa-getinfo/webupdate_notify.py", line 3, in <module>

    from bs4 import BeautifulSoup
ModuleNotFoundError: No module named 'bs4'

Traceback (most recent call last):
  File "/home/pi/Documents/Github/cocoa-getinfo/webupdate_notify.py", line 6, in <module>

    import cocoa_analysis
  File "/home/pi/Documents/Github/cocoa-getinfo/cocoa_analysis.py", line 3, in <module>
    from sub_sys import cocoa_pyocr
  File "/home/pi/Documents/Github/cocoa-getinfo/sub_sys/cocoa_pyocr.py", line 3, in <module>
    from PIL import Image
ModuleNotFoundError: No module named 'PIL'

Traceback (most recent call last):
  File "/home/pi/Documents/Github/cocoa-getinfo/webupdate_notify.py", line 6, in <module>

    import cocoa_analysis
  File "/home/pi/Documents/Github/cocoa-getinfo/cocoa_analysis.py", line 3, in <module>
    from sub_sys import cocoa_pyocr
  File "/home/pi/Documents/Github/cocoa-getinfo/sub_sys/cocoa_pyocr.py", line 4, in <module>
    import pyocr
ModuleNotFoundError: No module named 'pyocr'

Traceback (most recent call last):
  File "/home/pi/Documents/Github/cocoa-getinfo/webupdate_notify.py", line 6, in <module>

    import cocoa_analysis
  File "/home/pi/Documents/Github/cocoa-getinfo/cocoa_analysis.py", line 3, in <module>
    from sub_sys import cocoa_pyocr
  File "/home/pi/Documents/Github/cocoa-getinfo/sub_sys/cocoa_pyocr.py", line 4, in <module>
    import pyocr
ModuleNotFoundError: No module named 'pyocr'

Traceback (most recent call last):
  File "/home/pi/Documents/Github/cocoa-getinfo/webupdate_notify.py", line 6, in <module>

    import cocoa_analysis
  File "/home/pi/Documents/Github/cocoa-getinfo/cocoa_analysis.py", line 3, in <module>
    from sub_sys import cocoa_pyocr
  File "/home/pi/Documents/Github/cocoa-getinfo/sub_sys/cocoa_pyocr.py", line 4, in <module>
    import pyocr
ModuleNotFoundError: No module named 'pyocr'

Traceback (most recent call last):
  File "/home/pi/Documents/Github/cocoa-getinfo/webupdate_notify.py", line 6, in <module>

    import cocoa_analysis
  File "/home/pi/Documents/Github/cocoa-getinfo/cocoa_analysis.py", line 3, in <module>
    from sub_sys import cocoa_pyocr
  File "/home/pi/Documents/Github/cocoa-getinfo/sub_sys/cocoa_pyocr.py", line 4, in <module>
    import pyocr
ModuleNotFoundError: No module named 'pyocr'

Traceback (most recent call last):
  File "/home/pi/Documents/Github/cocoa-getinfo/webupdate_notify.py", line 6, in <module>

    import cocoa_analysis
  File "/home/pi/Documents/Github/cocoa-getinfo/cocoa_analysis.py", line 4, in <module>
    from sub_sys import cocoa_wordsearch_datapush
  File "/home/pi/Documents/Github/cocoa-getinfo/sub_sys/cocoa_wordsearch_datapush.py", line 9, in <module>
    import gspread
ModuleNotFoundError: No module named 'gspread'

Traceback (most recent call last):
  File "/home/pi/Documents/Github/cocoa-getinfo/webupdate_notify.py", line 6, in <module>

    import cocoa_analysis
  File "/home/pi/Documents/Github/cocoa-getinfo/cocoa_analysis.py", line 4, in <module>
    from sub_sys import cocoa_wordsearch_datapush
  File "/home/pi/Documents/Github/cocoa-getinfo/sub_sys/cocoa_wordsearch_datapush.py", line 10, in <module>
    from oauth2client.service_account import ServiceAccountCredentials
ModuleNotFoundError: No module named 'oauth2client'

Traceback (most recent call last):
  File "/home/pi/Documents/Github/cocoa-getinfo/webupdate_notify.py", line 6, in <module>

    import cocoa_analysis
  File "/home/pi/Documents/Github/cocoa-getinfo/cocoa_analysis.py", line 7, in <module>
    from sub_sys import cocoa_gspread_pull
  File "/home/pi/Documents/Github/cocoa-getinfo/sub_sys/cocoa_gspread_pull.py", line 2, in <module>
    from pylab import rcParams
ModuleNotFoundError: No module named 'pylab'

Traceback (most recent call last):
  File "/home/pi/Documents/Github/cocoa-getinfo/webupdate_notify.py", line 6, in <module>

    import cocoa_analysis
  File "/home/pi/Documents/Github/cocoa-getinfo/cocoa_analysis.py", line 7, in <module>
    from sub_sys import cocoa_gspread_pull
  File "/home/pi/Documents/Github/cocoa-getinfo/sub_sys/cocoa_gspread_pull.py", line 2, in <module>
    from pylab import rcParams
ModuleNotFoundError: No module named 'pylab'

Traceback (most recent call last):
  File "/home/pi/Documents/Github/cocoa-getinfo/webupdate_notify.py", line 6, in <module>

    import cocoa_analysis
  File "/home/pi/Documents/Github/cocoa-getinfo/cocoa_analysis.py", line 7, in <module>
    from sub_sys import cocoa_gspread_pull
  File "/home/pi/Documents/Github/cocoa-getinfo/sub_sys/cocoa_gspread_pull.py", line 2, in <module>
    from pylab import rcParams
ModuleNotFoundError: No module named 'pylab'

1615017600324
Traceback (most recent call last):
  File "/home/pi/Documents/Github/cocoa-getinfo/webupdate_notify.py", line 6, in <module>

    import cocoa_analysis
  File "/home/pi/Documents/Github/cocoa-getinfo/cocoa_analysis.py", line 7, in <module>
    from sub_sys import cocoa_gspread_pull
  File "/home/pi/Documents/Github/cocoa-getinfo/sub_sys/cocoa_gspread_pull.py", line 2, in <module>
    from pylab import rcParams
  File "/home/pi/.local/lib/python3.7/site-packages/pylab.py", line 1, in <module>
    from matplotlib.pylab import *
  File "/home/pi/.local/lib/python3.7/site-packages/matplotlib/__init__.py", line 107, in <module>

    from . import cbook, rcsetup
  File "/home/pi/.local/lib/python3.7/site-packages/matplotlib/cbook/__init__.py", line 28, in <module>
    import numpy as np
  File "/home/pi/.local/lib/python3.7/site-packages/numpy/__init__.py", line 148, in <module>
    from . import lib
  File "/home/pi/.local/lib/python3.7/site-packages/numpy/lib/__init__.py", line 25, in <module>
    from .index_tricks import *
  File "/home/pi/.local/lib/python3.7/site-packages/numpy/lib/index_tricks.py", line 12, in <module>
    import numpy.matrixlib as matrixlib
  File "/home/pi/.local/lib/python3.7/site-packages/numpy/matrixlib/__init__.py", line 4, in <module>
    from .defmatrix import *
  File "/home/pi/.local/lib/python3.7/site-packages/numpy/matrixlib/defmatrix.py", line 11, in <module>
    from numpy.linalg import matrix_power
  File "/home/pi/.local/lib/python3.7/site-packages/numpy/linalg/__init__.py", line 73, in <module>
    from .linalg import *
  File "/home/pi/.local/lib/python3.7/site-packages/numpy/linalg/linalg.py", line 33, in <module>
    from numpy.linalg import lapack_lite, _umath_linalg
ImportError: liblapack.so.3: cannot open shared object file: No such file or directory

1615035806443
1615104013351
Traceback (most recent call last):
  File "/home/pi/Documents/Github/cocoa-getinfo/webupdate_notify.py", line 6, in <module>

    import cocoa_analysis
  File "/home/pi/Documents/Github/cocoa-getinfo/cocoa_analysis.py", line 7, in <module>
    from sub_sys import cocoa_gspread_pull
  File "/home/pi/Documents/Github/cocoa-getinfo/sub_sys/cocoa_gspread_pull.py", line 3, in <module>
    from sub_sys import cocoa_create_plot
  File "/home/pi/Documents/Github/cocoa-getinfo/sub_sys/cocoa_create_plot.py", line 2, in <module>
    import seaborn as sns
ModuleNotFoundError: No module named 'seaborn'

Traceback (most recent call last):
  File "/home/pi/Documents/Github/cocoa-getinfo/webupdate_notify.py", line 6, in <module>

    import cocoa_analysis
  File "/home/pi/Documents/Github/cocoa-getinfo/cocoa_analysis.py", line 7, in <module>
    from sub_sys import cocoa_gspread_pull
  File "/home/pi/Documents/Github/cocoa-getinfo/sub_sys/cocoa_gspread_pull.py", line 3, in <module>

    from sub_sys import cocoa_create_plot
  File "/home/pi/Documents/Github/cocoa-getinfo/sub_sys/cocoa_create_plot.py", line 14, in <module>

    import japanize_matplotlib #matplotlib日本語モジュール
ModuleNotFoundError: No module named 'japanize_matplotlib'

1615190413008
1615276812705
1615363213308
Traceback (most recent call last):
  File "/home/pi/Documents/Github/cocoa-getinfo/webupdate_notify.py", line 85, in <module>

    cocoa_analysis.main_process()
  File "/home/pi/Documents/Github/cocoa-getinfo/cocoa_analysis.py", line 23, in main_process
    cocoa_wordsearch_datapush.search_and_push(1)
  File "/home/pi/Documents/Github/cocoa-getinfo/sub_sys/cocoa_wordsearch_datapush.py", line 121, in search_and_push
    if found == 'N/A' and found2 == 'N/A':  # 追加処理のみ更新無
UnboundLocalError: local variable 'found' referenced before assignment


1615449613114
1615536012300
1615622413645
1615708812994
1615795212533
Traceback (most recent call last):
  File "/home/pi/Documents/Github/cocoa-getinfo/webupdate_notify.py", line 85, in <module>
    cocoa_analysis.main_process()
  File "/home/pi/Documents/Github/cocoa-getinfo/cocoa_analysis.py", line 23, in main_process

    cocoa_wordsearch_datapush.search_and_push(1)
  File "/home/pi/Documents/Github/cocoa-getinfo/sub_sys/cocoa_wordsearch_datapush.py", line 153, in search_and_push

    print("陽性者登録数 : " + found2 + "\n")
UnboundLocalError: local variable 'found2' referenced before assignment

1615881612958
1615968012667
Traceback (most recent call last):
  File "/home/pi/Documents/Github/cocoa-getinfo/webupdate_notify.py", line 85, in <module>

    cocoa_analysis.main_process()
  File "/home/pi/Documents/Github/cocoa-getinfo/cocoa_analysis.py", line 23, in main_process
    cocoa_wordsearch_datapush.search_and_push(1)
  File "/home/pi/Documents/Github/cocoa-getinfo/sub_sys/cocoa_wordsearch_datapush.py", line 121, in search_and_push

    if found == 'N/A' and found2 == 'N/A':  # 追加処理のみ更新無
UnboundLocalError: local variable 'found' referenced before assignment

Traceback (most recent call last):
  File "/home/pi/Documents/Github/cocoa-getinfo/webupdate_notify.py", line 85, in <module>

    cocoa_analysis.main_process()
  File "/home/pi/Documents/Github/cocoa-getinfo/cocoa_analysis.py", line 23, in main_process
    cocoa_wordsearch_datapush.search_and_push(1)
  File "/home/pi/Documents/Github/cocoa-getinfo/sub_sys/cocoa_wordsearch_datapush.py", line 121, in search_and_push
    if found == 'N/A' and found2 == 'N/A':  # 追加処理のみ更新無
UnboundLocalError: local variable 'found' referenced before assignment

1616054412280
1616140812516
1616227213039
1616313612845
1616400012686
Traceback (most recent call last):
  File "/home/pi/Documents/Github/cocoa-getinfo/webupdate_notify.py", line 85, in <module>

    cocoa_analysis.main_process()
  File "/home/pi/Documents/Github/cocoa-getinfo/cocoa_analysis.py", line 23, in main_process
    cocoa_wordsearch_datapush.search_and_push(1)
  File "/home/pi/Documents/Github/cocoa-getinfo/sub_sys/cocoa_wordsearch_datapush.py", line 153, in search_and_push
    print("陽性者登録数 : " + found2 + "\n")
UnboundLocalError: local variable 'found2' referenced before assignment

Traceback (most recent call last):
  File "/home/pi/Documents/Github/cocoa-getinfo/webupdate_notify.py", line 85, in <module>

    cocoa_analysis.main_process()
  File "/home/pi/Documents/Github/cocoa-getinfo/cocoa_analysis.py", line 23, in main_process
    cocoa_wordsearch_datapush.search_and_push(1)
  File "/home/pi/Documents/Github/cocoa-getinfo/sub_sys/cocoa_wordsearch_datapush.py", line 153, in search_and_push
    print("陽性者登録数 : " + found2 + "\n")
UnboundLocalError: local variable 'found2' referenced before assignment

Traceback (most recent call last):
  File "/home/pi/Documents/Github/cocoa-getinfo/webupdate_notify.py", line 85, in <module>

    cocoa_analysis.main_process()
  File "/home/pi/Documents/Github/cocoa-getinfo/cocoa_analysis.py", line 23, in main_process
    cocoa_wordsearch_datapush.search_and_push(1)
  File "/home/pi/Documents/Github/cocoa-getinfo/sub_sys/cocoa_wordsearch_datapush.py", line 121, in search_and_push
    if found == 'N/A' and found2 == 'N/A':  # 追加処理のみ更新無
UnboundLocalError: local variable 'found' referenced before assignment

1616486412577
1616572812989
1616659212480
Traceback (most recent call last):
  File "/home/pi/Documents/Github/cocoa-getinfo/webupdate_notify.py", line 85, in <module>

    cocoa_analysis.main_process()
  File "/home/pi/Documents/Github/cocoa-getinfo/cocoa_analysis.py", line 23, in main_process
    cocoa_wordsearch_datapush.search_and_push(1)
  File "/home/pi/Documents/Github/cocoa-getinfo/sub_sys/cocoa_wordsearch_datapush.py", line 153, in search_and_push
    print("陽性者登録数 : " + found2 + "\n")

UnboundLocalError: local variable 'found2' referenced before assignment

Traceback (most recent call last):
  File "/home/pi/Documents/Github/cocoa-getinfo/webupdate_notify.py", line 85, in <module>
    cocoa_analysis.main_process()
  File "/home/pi/Documents/Github/cocoa-getinfo/cocoa_analysis.py", line 23, in main_process
    cocoa_wordsearch_datapush.search_and_push(1)
  File "/home/pi/Documents/Github/cocoa-getinfo/sub_sys/cocoa_wordsearch_datapush.py", line 153, in search_and_push
    print("陽性者登録数 : " + found2 + "\n")
UnboundLocalError: local variable 'found2' referenced before assignment

Traceback (most recent call last):
  File "/home/pi/Documents/Github/cocoa-getinfo/webupdate_notify.py", line 85, in <module>

    cocoa_analysis.main_process()
  File "/home/pi/Documents/Github/cocoa-getinfo/cocoa_analysis.py", line 23, in main_process
    cocoa_wordsearch_datapush.search_and_push(1)
  File "/home/pi/Documents/Github/cocoa-getinfo/sub_sys/cocoa_wordsearch_datapush.py", line 121, in search_and_push
    if found == 'N/A' and found2 == 'N/A':  # 追加処理のみ更新無
UnboundLocalError: local variable 'found2' referenced before assignment

Traceback (most recent call last):
  File "/home/pi/Documents/Github/cocoa-getinfo/webupdate_notify.py", line 85, in <module>

    cocoa_analysis.main_process()
  File "/home/pi/Documents/Github/cocoa-getinfo/cocoa_analysis.py", line 23, in main_process
    cocoa_wordsearch_datapush.search_and_push(1)
  File "/home/pi/Documents/Github/cocoa-getinfo/sub_sys/cocoa_wordsearch_datapush.py", line 153, in search_and_push
    print("陽性者登録数 : " + found2 + "\n")
UnboundLocalError: local variable 'found2' referenced before assignment

Traceback (most recent call last):
  File "/home/pi/Documents/Github/cocoa-getinfo/webupdate_notify.py", line 85, in <module>

    cocoa_analysis.main_process()
  File "/home/pi/Documents/Github/cocoa-getinfo/cocoa_analysis.py", line 23, in main_process
    cocoa_wordsearch_datapush.search_and_push(1)
  File "/home/pi/Documents/Github/cocoa-getinfo/sub_sys/cocoa_wordsearch_datapush.py", line 153, in search_and_push
    print("陽性者登録数 : " + found2 + "\n")
UnboundLocalError: local variable 'found2' referenced before assignment

Traceback (most recent call last):
  File "/home/pi/Documents/Github/cocoa-getinfo/webupdate_notify.py", line 85, in <module>

    cocoa_analysis.main_process()
  File "/home/pi/Documents/Github/cocoa-getinfo/cocoa_analysis.py", line 23, in main_process
    cocoa_wordsearch_datapush.search_and_push(1)
  File "/home/pi/Documents/Github/cocoa-getinfo/sub_sys/cocoa_wordsearch_datapush.py", line 121, in search_and_push
    if found == 'N/A' and found2 == 'N/A':  # 追加処理のみ更新無
UnboundLocalError: local variable 'found' referenced before assignment

Traceback (most recent call last):
  File "/home/pi/Documents/Github/cocoa-getinfo/webupdate_notify.py", line 85, in <module>

    cocoa_analysis.main_process()
  File "/home/pi/Documents/Github/cocoa-getinfo/cocoa_analysis.py", line 20, in main_process
    cocoa_pyocr.py_ocr()
  File "/home/pi/Documents/Github/cocoa-getinfo/sub_sys/cocoa_pyocr.py", line 33, in py_ocr
    img_out = img_in.crop((55, 70, 320, 160)) #50,50,320,160
  File "/home/pi/.local/lib/python3.7/site-packages/PIL/Image.py", line 1138, in crop

    self.load()
  File "/home/pi/.local/lib/python3.7/site-packages/PIL/ImageFile.py", line 284, in load

    raise_oserror(err_code)
  File "/home/pi/.local/lib/python3.7/site-packages/PIL/ImageFile.py", line 67, in raise_oserror
    raise OSError(message + " when reading image file")
OSError: unrecognized data stream contents when reading image file

Traceback (most recent call last):
  File "/home/pi/Documents/Github/cocoa-getinfo/webupdate_notify.py", line 85, in <module>

    cocoa_analysis.main_process()
  File "/home/pi/Documents/Github/cocoa-getinfo/cocoa_analysis.py", line 23, in main_process
    cocoa_wordsearch_datapush.search_and_push(1)
  File "/home/pi/Documents/Github/cocoa-getinfo/sub_sys/cocoa_wordsearch_datapush.py", line 153, in search_and_push
    print("陽性者登録数 : " + found2 + "\n")
UnboundLocalError: local variable 'found2' referenced before assignment

Traceback (most recent call last):
  File "/home/pi/.local/lib/python3.7/site-packages/PIL/ImageFile.py", line 247, in load

    s = read(self.decodermaxblock)
  File "/home/pi/.local/lib/python3.7/site-packages/PIL/PngImagePlugin.py", line 896, in load_read

    cid, pos, length = self.png.read()
  File "/home/pi/.local/lib/python3.7/site-packages/PIL/PngImagePlugin.py", line 162, in read

    length = i32(s)
  File "/home/pi/.local/lib/python3.7/site-packages/PIL/_binary.py", line 75, in i32be
    return unpack_from(">I", c, o)[0]
struct.error: unpack_from requires a buffer of at least 4 bytes

The above exception was the direct cause of the following exception:

Traceback (most recent call last):
  File "/home/pi/Documents/Github/cocoa-getinfo/webupdate_notify.py", line 85, in <module>
    cocoa_analysis.main_process()
  File "/home/pi/Documents/Github/cocoa-getinfo/cocoa_analysis.py", line 20, in main_process
    cocoa_pyocr.py_ocr()
  File "/home/pi/Documents/Github/cocoa-getinfo/sub_sys/cocoa_pyocr.py", line 33, in py_ocr
    img_out = img_in.crop((55, 70, 320, 160)) #50,50,320,160
  File "/home/pi/.local/lib/python3.7/site-packages/PIL/Image.py", line 1138, in crop

    self.load()
  File "/home/pi/.local/lib/python3.7/site-packages/PIL/ImageFile.py", line 253, in load

    raise OSError("image file is truncated") from e
OSError: image file is truncated

Traceback (most recent call last):
  File "/home/pi/Documents/Github/cocoa-getinfo/webupdate_notify.py", line 85, in <module>

    cocoa_analysis.main_process()
  File "/home/pi/Documents/Github/cocoa-getinfo/cocoa_analysis.py", line 23, in main_process
    cocoa_wordsearch_datapush.search_and_push(1)
  File "/home/pi/Documents/Github/cocoa-getinfo/sub_sys/cocoa_wordsearch_datapush.py", line 153, in search_and_push
    print("陽性者登録数 : " + found2 + "\n")
UnboundLocalError: local variable 'found2' referenced before assignment

1616665550550
1616745613523
1616832000090
Traceback (most recent call last):
  File "/home/pi/.local/lib/python3.7/site-packages/urllib3/connection.py", line 170, in _new_conn

    (self._dns_host, self.port), self.timeout, **extra_kw
  File "/home/pi/.local/lib/python3.7/site-packages/urllib3/util/connection.py", line 73, in create_connection
    for res in socket.getaddrinfo(host, port, family, socket.SOCK_STREAM):
  File "/usr/local/lib/python3.7/socket.py", line 748, in getaddrinfo

    for res in _socket.getaddrinfo(host, port, family, type, proto, flags):
socket.gaierror: [Errno -3] Temporary failure in name resolution

During handling of the above exception, another exception occurred:

Traceback (most recent call last):
  File "/home/pi/.local/lib/python3.7/site-packages/urllib3/connectionpool.py", line 706, in urlopen

    chunked=chunked,
  File "/home/pi/.local/lib/python3.7/site-packages/urllib3/connectionpool.py", line 382, in _make_request
    self._validate_conn(conn)
  File "/home/pi/.local/lib/python3.7/site-packages/urllib3/connectionpool.py", line 1010, in _validate_conn
    conn.connect()
  File "/home/pi/.local/lib/python3.7/site-packages/urllib3/connection.py", line 353, in connect
    conn = self._new_conn()
  File "/home/pi/.local/lib/python3.7/site-packages/urllib3/connection.py", line 182, in _new_conn
    self, "Failed to establish a new connection: %s" % e
urllib3.exceptions.NewConnectionError: <urllib3.connection.HTTPSConnection object at 0x6fdb8330>: Failed to establish a new connection: [Errno -3] Temporary failure in name resolution

During handling of the above exception, another exception occurred:

Traceback (most recent call last):
  File "/home/pi/.local/lib/python3.7/site-packages/requests/adapters.py", line 449, in send
    timeout=timeout
  File "/home/pi/.local/lib/python3.7/site-packages/urllib3/connectionpool.py", line 756, in urlopen
    method, url, error=e, _pool=self, _stacktrace=sys.exc_info()[2]
  File "/home/pi/.local/lib/python3.7/site-packages/urllib3/util/retry.py", line 573, in increment
    raise MaxRetryError(_pool, url, error or ResponseError(cause))
urllib3.exceptions.MaxRetryError: HTTPSConnectionPool(host='www.mhlw.go.jp', port=443): Max retries exceeded with url: /stf/seisakunitsuite/bunya/cocoa_00138.html (Caused by NewConnectionError('<urllib3.connection.HTTPSConnection object at 0x6fdb8330>: Failed to establish a new connection: [Errno -3] Temporary failure in name resolution'))

During handling of the above exception, another exception occurred:

Traceback (most recent call last):
  File "/home/pi/Documents/Github/cocoa-getinfo/webupdate_notify.py", line 104, in <module>
    cocoa_analysis_holiday.main_process()
  File "/home/pi/Documents/Github/cocoa-getinfo/cocoa_analysis_holiday.py", line 14, in main_process
    cocoa_fetch.fetch_image()
  File "/home/pi/Documents/Github/cocoa-getinfo/sub_sys/cocoa_fetch.py", line 25, in fetch_image
    html = requests.get(load_url, headers=headers)
  File "/home/pi/.local/lib/python3.7/site-packages/requests/api.py", line 76, in get
    return request('get', url, params=params, **kwargs)
  File "/home/pi/.local/lib/python3.7/site-packages/requests/api.py", line 61, in request
    return session.request(method=method, url=url, **kwargs)
  File "/home/pi/.local/lib/python3.7/site-packages/requests/sessions.py", line 542, in request
    resp = self.send(prep, **send_kwargs)
  File "/home/pi/.local/lib/python3.7/site-packages/requests/sessions.py", line 655, in send
    r = adapter.send(request, **kwargs)
  File "/home/pi/.local/lib/python3.7/site-packages/requests/adapters.py", line 516, in send
    raise ConnectionError(e, request=request)
requests.exceptions.ConnectionError: HTTPSConnectionPool(host='www.mhlw.go.jp', port=443): Max retries exceeded with url: /stf/seisakunitsuite/bunya/cocoa_00138.html (Caused by NewConnectionError('<urllib3.connection.HTTPSConnection object at 0x6fdb8330>: Failed to establish a new connection: [Errno -3] Temporary failure in name resolution'))

1616918400095
Traceback (most recent call last):
  File "/home/pi/.local/lib/python3.7/site-packages/urllib3/connection.py", line 170, in _new_conn

    (self._dns_host, self.port), self.timeout, **extra_kw
  File "/home/pi/.local/lib/python3.7/site-packages/urllib3/util/connection.py", line 96, in create_connection

    raise err
  File "/home/pi/.local/lib/python3.7/site-packages/urllib3/util/connection.py", line 86, in create_connection
    sock.connect(sa)
TimeoutError: [Errno 110] Connection timed out

During handling of the above exception, another exception occurred:

Traceback (most recent call last):
  File "/home/pi/.local/lib/python3.7/site-packages/urllib3/connectionpool.py", line 706, in urlopen

    chunked=chunked,
  File "/home/pi/.local/lib/python3.7/site-packages/urllib3/connectionpool.py", line 382, in _make_request
    self._validate_conn(conn)
  File "/home/pi/.local/lib/python3.7/site-packages/urllib3/connectionpool.py", line 1010, in _validate_conn

    conn.connect()
  File "/home/pi/.local/lib/python3.7/site-packages/urllib3/connection.py", line 353, in connect
    conn = self._new_conn()
  File "/home/pi/.local/lib/python3.7/site-packages/urllib3/connection.py", line 182, in _new_conn
    self, "Failed to establish a new connection: %s" % e
urllib3.exceptions.NewConnectionError: <urllib3.connection.HTTPSConnection object at 0x6fd97370>: Failed to establish a new connection: [Errno 110] Connection timed out

During handling of the above exception, another exception occurred:

Traceback (most recent call last):
  File "/home/pi/.local/lib/python3.7/site-packages/requests/adapters.py", line 449, in send
    timeout=timeout
  File "/home/pi/.local/lib/python3.7/site-packages/urllib3/connectionpool.py", line 756, in urlopen
    method, url, error=e, _pool=self, _stacktrace=sys.exc_info()[2]
  File "/home/pi/.local/lib/python3.7/site-packages/urllib3/util/retry.py", line 573, in increment
    raise MaxRetryError(_pool, url, error or ResponseError(cause))
urllib3.exceptions.MaxRetryError: HTTPSConnectionPool(host='www.mhlw.go.jp', port=443): Max retries exceeded with url: /stf/seisakunitsuite/bunya/cocoa_00138.html (Caused by NewConnectionError('<urllib3.connection.HTTPSConnection object at 0x6fd97370>: Failed to establish a new connection: [Errno 110] Connection timed out'))

During handling of the above exception, another exception occurred:

Traceback (most recent call last):
  File "/home/pi/Documents/Github/cocoa-getinfo/webupdate_notify.py", line 104, in <module>
    cocoa_analysis_holiday.main_process()
  File "/home/pi/Documents/Github/cocoa-getinfo/cocoa_analysis_holiday.py", line 14, in main_process
    cocoa_fetch.fetch_image()
  File "/home/pi/Documents/Github/cocoa-getinfo/sub_sys/cocoa_fetch.py", line 25, in fetch_image
    html = requests.get(load_url, headers=headers)
  File "/home/pi/.local/lib/python3.7/site-packages/requests/api.py", line 76, in get
    return request('get', url, params=params, **kwargs)
  File "/home/pi/.local/lib/python3.7/site-packages/requests/api.py", line 61, in request
    return session.request(method=method, url=url, **kwargs)
  File "/home/pi/.local/lib/python3.7/site-packages/requests/sessions.py", line 542, in request
    resp = self.send(prep, **send_kwargs)
  File "/home/pi/.local/lib/python3.7/site-packages/requests/sessions.py", line 655, in send
    r = adapter.send(request, **kwargs)
  File "/home/pi/.local/lib/python3.7/site-packages/requests/adapters.py", line 516, in send
    raise ConnectionError(e, request=request)
requests.exceptions.ConnectionError: HTTPSConnectionPool(host='www.mhlw.go.jp', port=443): Max retries exceeded with url: /stf/seisakunitsuite/bunya/cocoa_00138.html (Caused by NewConnectionError('<urllib3.connection.HTTPSConnection object at 0x6fd97370>: Failed to establish a new connection: [Errno 110] Connection timed out'))

1617004800062
Traceback (most recent call last):
  File "/home/pi/.local/lib/python3.7/site-packages/urllib3/connection.py", line 170, in _new_conn

    (self._dns_host, self.port), self.timeout, **extra_kw
  File "/home/pi/.local/lib/python3.7/site-packages/urllib3/util/connection.py", line 73, in create_connection
    for res in socket.getaddrinfo(host, port, family, socket.SOCK_STREAM):
  File "/usr/local/lib/python3.7/socket.py", line 748, in getaddrinfo

    for res in _socket.getaddrinfo(host, port, family, type, proto, flags):
socket.gaierror: [Errno -3] Temporary failure in name resolution

During handling of the above exception, another exception occurred:

Traceback (most recent call last):
  File "/home/pi/.local/lib/python3.7/site-packages/urllib3/connectionpool.py", line 706, in urlopen

    chunked=chunked,
  File "/home/pi/.local/lib/python3.7/site-packages/urllib3/connectionpool.py", line 382, in _make_request

    self._validate_conn(conn)
  File "/home/pi/.local/lib/python3.7/site-packages/urllib3/connectionpool.py", line 1010, in _validate_conn
    conn.connect()
  File "/home/pi/.local/lib/python3.7/site-packages/urllib3/connection.py", line 353, in connect
    conn = self._new_conn()
  File "/home/pi/.local/lib/python3.7/site-packages/urllib3/connection.py", line 182, in _new_conn
    self, "Failed to establish a new connection: %s" % e
urllib3.exceptions.NewConnectionError: <urllib3.connection.HTTPSConnection object at 0x6fdd5350>: Failed to establish a new connection: [Errno -3] Temporary failure in name resolution

During handling of the above exception, another exception occurred:

Traceback (most recent call last):
  File "/home/pi/.local/lib/python3.7/site-packages/requests/adapters.py", line 449, in send
    timeout=timeout
  File "/home/pi/.local/lib/python3.7/site-packages/urllib3/connectionpool.py", line 756, in urlopen
    method, url, error=e, _pool=self, _stacktrace=sys.exc_info()[2]
  File "/home/pi/.local/lib/python3.7/site-packages/urllib3/util/retry.py", line 573, in increment
    raise MaxRetryError(_pool, url, error or ResponseError(cause))
urllib3.exceptions.MaxRetryError: HTTPSConnectionPool(host='www.mhlw.go.jp', port=443): Max retries exceeded with url: /stf/seisakunitsuite/bunya/cocoa_00138.html (Caused by NewConnectionError('<urllib3.connection.HTTPSConnection object at 0x6fdd5350>: Failed to establish a new connection: [Errno -3] Temporary failure in name resolution'))

During handling of the above exception, another exception occurred:

Traceback (most recent call last):
  File "/home/pi/Documents/Github/cocoa-getinfo/webupdate_notify.py", line 75, in <module>
    if(web_update()):
  File "/home/pi/Documents/Github/cocoa-getinfo/webupdate_notify.py", line 35, in web_update
    html = requests.get(load_url, headers=headers)
  File "/home/pi/.local/lib/python3.7/site-packages/requests/api.py", line 76, in get
    return request('get', url, params=params, **kwargs)
  File "/home/pi/.local/lib/python3.7/site-packages/requests/api.py", line 61, in request
    return session.request(method=method, url=url, **kwargs)
  File "/home/pi/.local/lib/python3.7/site-packages/requests/sessions.py", line 542, in request
    resp = self.send(prep, **send_kwargs)
  File "/home/pi/.local/lib/python3.7/site-packages/requests/sessions.py", line 655, in send
    r = adapter.send(request, **kwargs)
  File "/home/pi/.local/lib/python3.7/site-packages/requests/adapters.py", line 516, in send
    raise ConnectionError(e, request=request)
requests.exceptions.ConnectionError: HTTPSConnectionPool(host='www.mhlw.go.jp', port=443): Max retries exceeded with url: /stf/seisakunitsuite/bunya/cocoa_00138.html (Caused by NewConnectionError('<urllib3.connection.HTTPSConnection object at 0x6fdd5350>: Failed to establish a new connection: [Errno -3] Temporary failure in name resolution'))

1617183894589
Traceback (most recent call last):
  File "/home/pi/Documents/Github/cocoa-getinfo/webupdate_notify.py", line 85, in <module>

    cocoa_analysis.main_process()
  File "/home/pi/Documents/Github/cocoa-getinfo/cocoa_analysis.py", line 23, in main_process
    cocoa_wordsearch_datapush.search_and_push(1)
  File "/home/pi/Documents/Github/cocoa-getinfo/sub_sys/cocoa_wordsearch_datapush.py", line 121, in search_and_push

    if found == 'N/A' and found2 == 'N/A':  # 追加処理のみ更新無
UnboundLocalError: local variable 'found' referenced before assignment

Traceback (most recent call last):
  File "/home/pi/Documents/Github/cocoa-getinfo/webupdate_notify.py", line 85, in <module>

    cocoa_analysis.main_process()
  File "/home/pi/Documents/Github/cocoa-getinfo/cocoa_analysis.py", line 23, in main_process
    cocoa_wordsearch_datapush.search_and_push(1)
  File "/home/pi/Documents/Github/cocoa-getinfo/sub_sys/cocoa_wordsearch_datapush.py", line 121, in search_and_push
    if found == 'N/A' and found2 == 'N/A':  # 追加処理のみ更新無
UnboundLocalError: local variable 'found' referenced before assignment

1617184050713
Traceback (most recent call last):
  File "/home/pi/Documents/Github/cocoa-getinfo/webupdate_notify.py", line 85, in <module>
    cocoa_analysis.main_process()
  File "/home/pi/Documents/Github/cocoa-getinfo/cocoa_analysis.py", line 23, in main_process

    cocoa_wordsearch_datapush.search_and_push(1)
  File "/home/pi/Documents/Github/cocoa-getinfo/sub_sys/cocoa_wordsearch_datapush.py", line 121, in search_and_push
    if found == 'N/A' and found2 == 'N/A':  # 追加処理のみ更新無
UnboundLocalError: local variable 'found' referenced before assignment

1617184323040
Traceback (most recent call last):
  File "/home/pi/Documents/Github/cocoa-getinfo/webupdate_notify.py", line 85, in <module>

    cocoa_analysis.main_process()
  File "/home/pi/Documents/Github/cocoa-getinfo/cocoa_analysis.py", line 23, in main_process
    cocoa_wordsearch_datapush.search_and_push(1)
  File "/home/pi/Documents/Github/cocoa-getinfo/sub_sys/cocoa_wordsearch_datapush.py", line 153, in search_and_push
    print("陽性者登録数 : " + found2 + "\n")
UnboundLocalError: local variable 'found2' referenced before assignment

1617184405263
1617264012083
1617275228516
1617350412946
1617436812455
1617523213178
1617609612950
1617696012989
1617782412503
1617868812207
1617955212905
1617969604716
1617969888864
1618041613135
1618128012952
1618214412594
1618300812354
1618387212907
1618473612675
1618560012519
1618585406157
1618585735833
1618646411903
1618732813426
1618819212413
1618905613116
1618992013486
1619078412709
1619164813110
1619165443646
1619181882817
1619182608422
1619182827250
1619251212033
1619337613125
1619424013407
1619510412604
1619596812588
1619683212476
1619769612687
1619779515111
1619856012514
1619942412578
1620028812366
1620115212543
1620201612527
1620288012522
1620374413031
Traceback (most recent call last):
  File "/home/pi/Documents/Github/cocoa-getinfo/webupdate_notify.py", line 85, in <module>

    cocoa_analysis.main_process()
  File "/home/pi/Documents/Github/cocoa-getinfo/cocoa_analysis.py", line 23, in main_process
    cocoa_wordsearch_datapush.search_and_push(1)
  File "/home/pi/Documents/Github/cocoa-getinfo/sub_sys/cocoa_wordsearch_datapush.py", line 186, in search_and_push
    ffound = int(re.sub("\\D", "", found))
ValueError: invalid literal for int() with base 10: ''

1620385401541
1620460812490
1620547212712
1620633612943
1620720013003
1620806412821
1620892812981
1620979212797
1621065612966
1621152012847
1621238413329
1621324812210
1621411213600
1621497612455
1621584012968
1621592753198
1621670413132
1621756812597
1621843212851
1621929613396
1622016012830
1622102413450
1622188812994
1622200334820
1622200420205
1622275212753
1622361613010
1622448012422
1622534413195
1622620812638
1622707213148
1622793613103
Traceback (most recent call last):
  File "/home/pi/Documents/Github/cocoa-getinfo/webupdate_notify.py", line 85, in <module>

    cocoa_analysis.main_process()
  File "/home/pi/Documents/Github/cocoa-getinfo/cocoa_analysis.py", line 17, in main_process
    cocoa_fetch.fetch_image()
  File "/home/pi/Documents/Github/cocoa-getinfo/sub_sys/cocoa_fetch.py", line 38, in fetch_image
    img = base64.b64decode(imgcode_clear.encode())
  File "/usr/local/lib/python3.7/base64.py", line 87, in b64decode

    return binascii.a2b_base64(s)
binascii.Error: Incorrect padding

1622800405121
1622880012737
Traceback (most recent call last):
  File "/home/pi/Documents/Github/cocoa-getinfo/webupdate_notify.py", line 104, in <module>

    cocoa_analysis_holiday.main_process()
  File "/home/pi/Documents/Github/cocoa-getinfo/cocoa_analysis_holiday.py", line 14, in main_process
    cocoa_fetch.fetch_image()
  File "/home/pi/Documents/Github/cocoa-getinfo/sub_sys/cocoa_fetch.py", line 38, in fetch_image
    img = base64.b64decode(imgcode_clear.encode())
  File "/usr/local/lib/python3.7/base64.py", line 87, in b64decode

    return binascii.a2b_base64(s)
binascii.Error: Incorrect padding

1622966413178
Traceback (most recent call last):
  File "/home/pi/Documents/Github/cocoa-getinfo/webupdate_notify.py", line 104, in <module>

    cocoa_analysis_holiday.main_process()
  File "/home/pi/Documents/Github/cocoa-getinfo/cocoa_analysis_holiday.py", line 14, in main_process
    cocoa_fetch.fetch_image()
  File "/home/pi/Documents/Github/cocoa-getinfo/sub_sys/cocoa_fetch.py", line 38, in fetch_image
    img = base64.b64decode(imgcode_clear.encode())
  File "/usr/local/lib/python3.7/base64.py", line 87, in b64decode

    return binascii.a2b_base64(s)
binascii.
Error: Incorrect padding

1623052812669
Traceback (most recent call last):
  File "/home/pi/Documents/Github/cocoa-getinfo/cocoa_analysis_holiday.py", line 26, in <module>

    main_process()
  File "/home/pi/Documents/Github/cocoa-getinfo/cocoa_analysis_holiday.py", line 14, in main_process
    cocoa_fetch.fetch_image()
  File "/home/pi/Documents/Github/cocoa-getinfo/sub_sys/cocoa_fetch.py", line 38, in fetch_image
    img = base64.b64decode(imgcode_clear.encode())
  File "/usr/local/lib/python3.7/base64.py", line 87, in b64decode
    return binascii.a2b_base64(s)
binascii.Error: Incorrect padding

1623139212727
1623225612850
1623313917195
1623399487802
1623484812830
1623571213396
1623657613133
1623744012715
1623830414059
1623916812626
1624003213157
1624013114216
1624089620137
Traceback (most recent call last):
  File "/usr/local/lib/python3.7/http/client.py", line 877, in _get_hostport

    port = int(host[i+1:])
ValueError: invalid literal for int() with base 10: 'image'

During handling of the above exception, another exception occurred:

Traceback (most recent call last):
  File "/home/pi/Documents/Github/cocoa-getinfo/webupdate_notify.py", line 104, in <module>
    cocoa_analysis_holiday.main_process()
  File "/home/pi/Documents/Github/cocoa-getinfo/cocoa_analysis_holiday.py", line 14, in main_process
    cocoa_fetch.fetch_image()
  File "/home/pi/Documents/Github/cocoa-getinfo/sub_sys/cocoa_fetch.py", line 63, in fetch_image
    download_file(url, dst_path)
  File "/home/pi/Documents/Github/cocoa-getinfo/sub_sys/cocoa_fetch.py", line 14, in download_file
    with urllib.request.urlopen(url) as web_file:
  File "/usr/local/lib/python3.7/urllib/request.py", line 222, in urlopen
    return opener.open(url, data, timeout)
  File "/usr/local/lib/python3.7/urllib/request.py", line 525, in open
    response = self._open(req, data)
  File "/usr/local/lib/python3.7/urllib/request.py", line 543, in _open

    '_open', req)
  File "/usr/local/lib/python3.7/urllib/request.py", line 503, in _call_chain
    result = func(*args)
  File "/usr/local/lib/python3.7/urllib/request.py", line 1360, in https_open
    context=self._context, check_hostname=self._check_hostname)
  File "/usr/local/lib/python3.7/urllib/request.py", line 1285, in do_open

    h = http_class(host, timeout=req.timeout, **http_conn_args)
  File "/usr/local/lib/python3.7/http/client.py", line 1358, in __init__
    blocksize=blocksize)
  File "/usr/local/lib/python3.7/http/client.py", line 841, in __init__
    (self.host, self.port) = self._get_hostport(host, port)
  File "/usr/local/lib/python3.7/http/client.py", line 882, in _get_hostport

    raise InvalidURL("nonnumeric port: '%s'" % host[i+1:])
http.client.InvalidURL: nonnumeric port: 'image'

1624176012558
Traceback (most recent call last):
  File "/usr/local/lib/python3.7/http/client.py", line 877, in _get_hostport

    port = int(host[i+1:])
ValueError: invalid literal for int() with base 10: 'image'

During handling of the above exception, another exception occurred:

Traceback (most recent call last):
  File "/home/pi/Documents/Github/cocoa-getinfo/webupdate_notify.py", line 104, in <module>
    cocoa_analysis_holiday.main_process()
  File "/home/pi/Documents/Github/cocoa-getinfo/cocoa_analysis_holiday.py", line 14, in main_process

    cocoa_fetch.fetch_image()
  File "/home/pi/Documents/Github/cocoa-getinfo/sub_sys/cocoa_fetch.py", line 63, in fetch_image
    download_file(url, dst_path)
  File "/home/pi/Documents/Github/cocoa-getinfo/sub_sys/cocoa_fetch.py", line 14, in download_file
    with urllib.request.urlopen(url) as web_file:
  File "/usr/local/lib/python3.7/urllib/request.py", line 222, in urlopen
    return opener.open(url, data, timeout)
  File "/usr/local/lib/python3.7/urllib/request.py", line 525, in open
    response = self._open(req, data)
  File "/usr/local/lib/python3.7/urllib/request.py", line 543, in _open
    '_open', req)
  File "/usr/local/lib/python3.7/urllib/request.py", line 503, in _call_chain
    result = func(*args)
  File "/usr/local/lib/python3.7/urllib/request.py", line 1360, in https_open
    context=self._context, check_hostname=self._check_hostname)
  File "/usr/local/lib/python3.7/urllib/request.py", line 1285, in do_open
    h = http_class(host, timeout=req.timeout, **http_conn_args)
  File "/usr/local/lib/python3.7/http/client.py", line 1358, in __init__
    blocksize=blocksize)
  File "/usr/local/lib/python3.7/http/client.py", line 841, in __init__
    (self.host, self.port) = self._get_hostport(host, port)
  File "/usr/local/lib/python3.7/http/client.py", line 882, in _get_hostport
    raise InvalidURL("nonnumeric port: '%s'" % host[i+1:])
http.client.InvalidURL: nonnumeric port: 'image'

1624262413493
Traceback (most recent call last):
  File "/usr/local/lib/python3.7/http/client.py", line 877, in _get_hostport

    port = int(host[i+1:])
ValueError: invalid literal for int() with base 10: 'image'

During handling of the above exception, another exception occurred:

Traceback (most recent call last):
  File "/home/pi/Documents/Github/cocoa-getinfo/cocoa_analysis_holiday.py", line 26, in <module>
    main_process()
  File "/home/pi/Documents/Github/cocoa-getinfo/cocoa_analysis_holiday.py", line 14, in main_process
    cocoa_fetch.fetch_image()
  File "/home/pi/Documents/Github/cocoa-getinfo/sub_sys/cocoa_fetch.py", line 63, in fetch_image

    download_file(url, dst_path)
  File "/home/pi/Documents/Github/cocoa-getinfo/sub_sys/cocoa_fetch.py", line 14, in download_file
    with urllib.request.urlopen(url) as web_file:
  File "/usr/local/lib/python3.7/urllib/request.py", line 222, in urlopen
    return opener.open(url, data, timeout)
  File "/usr/local/lib/python3.7/urllib/request.py", line 525, in open
    response = self._open(req, data)
  File "/usr/local/lib/python3.7/urllib/request.py", line 543, in _open
    '_open', req)
  File "/usr/local/lib/python3.7/urllib/request.py", line 503, in _call_chain
    result = func(*args)
  File "/usr/local/lib/python3.7/urllib/request.py", line 1360, in https_open
    context=self._context, check_hostname=self._check_hostname)
  File "/usr/local/lib/python3.7/urllib/request.py", line 1285, in do_open
    h = http_class(host, timeout=req.timeout, **http_conn_args)
  File "/usr/local/lib/python3.7/http/client.py", line 1358, in __init__
    blocksize=blocksize)
  File "/usr/local/lib/python3.7/http/client.py", line 841, in __init__
    (self.host, self.port) = self._get_hostport(host, port)
  File "/usr/local/lib/python3.7/http/client.py", line 882, in _get_hostport
    raise InvalidURL("nonnumeric port: '%s'" % host[i+1:])
http.client.InvalidURL: nonnumeric port: 'image'

1624267037728
Traceback (most recent call last):
  File "/usr/local/lib/python3.7/http/client.py", line 877, in _get_hostport

    port = int(host[i+1:])
ValueError: invalid literal for int() with base 10: 'image'

During handling of the above exception, another exception occurred:

Traceback (most recent call last):
  File "/home/pi/Documents/Github/cocoa-getinfo/cocoa_analysis_holiday.py", line 26, in <module>
    main_process()
  File "/home/pi/Documents/Github/cocoa-getinfo/cocoa_analysis_holiday.py", line 14, in main_process

    cocoa_fetch.fetch_image()
  File "/home/pi/Documents/Github/cocoa-getinfo/sub_sys/cocoa_fetch.py", line 63, in fetch_image
    download_file(url, dst_path)
  File "/home/pi/Documents/Github/cocoa-getinfo/sub_sys/cocoa_fetch.py", line 14, in download_file
    with urllib.request.urlopen(url) as web_file:
  File "/usr/local/lib/python3.7/urllib/request.py", line 222, in urlopen
    return opener.open(url, data, timeout)
  File "/usr/local/lib/python3.7/urllib/request.py", line 525, in open
    response = self._open(req, data)
  File "/usr/local/lib/python3.7/urllib/request.py", line 543, in _open
    '_open', req)
  File "/usr/local/lib/python3.7/urllib/request.py", line 503, in _call_chain
    result = func(*args)
  File "/usr/local/lib/python3.7/urllib/request.py", line 1360, in https_open
    context=self._context, check_hostname=self._check_hostname)
  File "/usr/local/lib/python3.7/urllib/request.py", line 1285, in do_open
    h = http_class(host, timeout=req.timeout, **http_conn_args)
  File "/usr/local/lib/python3.7/http/client.py", line 1358, in __init__
    blocksize=blocksize)
  File "/usr/local/lib/python3.7/http/client.py", line 841, in __init__

    (self.host, self.port) = self._get_hostport(host, port)
  File "/usr/local/lib/python3.7/http/client.py", line 882, in _get_hostport

    raise InvalidURL("nonnumeric port: '%s'" % host[i+1:])
http.client.InvalidURL: nonnumeric port: 'image'

1624267351164
Traceback (most recent call last):
  File "/home/pi/Documents/Github/cocoa-getinfo/cocoa_analysis_holiday.py", line 26, in <module>
    main_process()
  File "/home/pi/Documents/Github/cocoa-getinfo/cocoa_analysis_holiday.py", line 14, in main_process
    cocoa_fetch.fetch_image()
  File "/home/pi/Documents/Github/cocoa-getinfo/sub_sys/cocoa_fetch.py", line 50, in fetch_image
    img = base64.b64decode(imgcode_clear.encode())
  File "/usr/local/lib/python3.7/base64.py", line 87, in b64decode

    return binascii.a2b_base64(s)
binascii.Error: Incorrect padding

1624267435910
Traceback (most recent call last):
  File "/home/pi/Documents/Github/cocoa-getinfo/cocoa_analysis_holiday.py", line 26, in <module>

    main_process()
  File "/home/pi/Documents/Github/cocoa-getinfo/cocoa_analysis_holiday.py", line 14, in main_process
    cocoa_fetch.fetch_image()
  File "/home/pi/Documents/Github/cocoa-getinfo/sub_sys/cocoa_fetch.py", line 50, in fetch_image
    img = base64.b64decode(imgcode_clear.encode())
  File "/usr/local/lib/python3.7/base64.py", line 87, in b64decode
    return binascii.a2b_base64(s)
binascii.Error: Incorrect padding

1624267508282
Traceback (most recent call last):
  File "/home/pi/Documents/Github/cocoa-getinfo/cocoa_analysis_holiday.py", line 26, in <module>
    main_process()
  File "/home/pi/Documents/Github/cocoa-getinfo/cocoa_analysis_holiday.py", line 14, in main_process

    cocoa_fetch.fetch_image()
  File "/home/pi/Documents/Github/cocoa-getinfo/sub_sys/cocoa_fetch.py", line 50, in fetch_image
    img = base64.b64decode(imgcode_clear.encode())
  File "/usr/local/lib/python3.7/base64.py", line 87, in b64decode
    return binascii.a2b_base64(s)
binascii.Error: Incorrect padding

1624267972751
/home/pi/.local/lib/python3.7/site-packages/PIL/Image.py:963: UserWarning: Palette images with Transparency expressed in bytes should be converted to RGBA images
  "Palette images with Transparency expressed in bytes should be "

1624268257492
Traceback (most recent call last):
  File "/home/pi/Documents/Github/cocoa-getinfo/cocoa_analysis_holiday.py", line 26, in <module>

    main_process()
  File "/home/pi/Documents/Github/cocoa-getinfo/cocoa_analysis_holiday.py", line 14, in main_process
    cocoa_fetch.fetch_image()
  File "/home/pi/Documents/Github/cocoa-getinfo/sub_sys/cocoa_fetch.py", line 45, in fetch_image
    imgcode = element[1].attrs['src']
  File "/home/pi/.local/lib/python3.7/site-packages/bs4/element.py", line 1406, in __getitem__

    return self.attrs[key]
KeyError: 1

1624268449378
/home/pi/.local/lib/python3.7/site-packages/PIL/Image.py:963: UserWarning: Palette images with Transparency expressed in bytes should be converted to RGBA images
  "Palette images with Transparency expressed in bytes should be "

1624268865205
/home/pi/.local/lib/python3.7/site-packages/PIL/Image.py:963: UserWarning: Palette images with Transparency expressed in bytes should be converted to RGBA images
  "Palette images with Transparency expressed in bytes should be "

1624269016250
/home/pi/.local/lib/python3.7/site-packages/PIL/Image.py:963: UserWarning: Palette images with Transparency expressed in bytes should be converted to RGBA images
  "Palette images with Transparency expressed in bytes should be "

1624269239588
Traceback (most recent call last):
  File "/home/pi/Documents/Github/cocoa-getinfo/cocoa_analysis_holiday.py", line 2, in <module>

    from sub_sys import cocoa_fetch
  File "/home/pi/Documents/Github/cocoa-getinfo/sub_sys/cocoa_fetch.py", line 40
    img_select = soup.select_one('#content > div.l-contentBody > div > div.l-contentMain > div:nth-child(4) > div > p:nth-child(7) > img'))
                                                                                                                                          ^
SyntaxError: invalid syntax

1624269268520
Traceback (most recent call last):
  File "/home/pi/Documents/Github/cocoa-getinfo/cocoa_analysis_holiday.py", line 2, in <module>

    from sub_sys import cocoa_fetch
  File "/home/pi/Documents/Github/cocoa-getinfo/sub_sys/cocoa_fetch.py", line 51
    """
      ^
IndentationError: unindent does not match any outer indentation level

1624269309711
Traceback (most recent call last):
  File "/home/pi/Documents/Github/cocoa-getinfo/cocoa_analysis_holiday.py", line 26, in <module>

    main_process()
  File "/home/pi/Documents/Github/cocoa-getinfo/cocoa_analysis_holiday.py", line 14, in main_process
    cocoa_fetch.fetch_image()
  File "/home/pi/Documents/Github/cocoa-getinfo/sub_sys/cocoa_fetch.py", line 41, in fetch_image
    imgcode_fit = img_select.replace('data:image/png;base64,', '')
TypeError: 'NoneType' object is not callable

1624269385546
1624348813401
1624435212912
1624521612540
1624608013314
1624632714251
1624694413426
Traceback (most recent call last):
  File "/home/pi/Documents/Github/cocoa-getinfo/webupdate_notify.py", line 104, in <module>

    cocoa_analysis_holiday.main_process()
  File "/home/pi/Documents/Github/cocoa-getinfo/cocoa_analysis_holiday.py", line 14, in main_process
    cocoa_fetch.fetch_image()
  File "/home/pi/Documents/Github/cocoa-getinfo/sub_sys/cocoa_fetch.py", line 44, in fetch_image
    img_decode = base64.b64decode(imgcode_fit.encode())
  File "/usr/local/lib/python3.7/base64.py", line 87, in b64decode

    return binascii.a2b_base64(s)
binascii.Error: Incorrect padding

1624780813162
Traceback (most recent call last):
  File "/home/pi/Documents/Github/cocoa-getinfo/webupdate_notify.py", line 104, in <module>

    cocoa_analysis_holiday.main_process()
  File "/home/pi/Documents/Github/cocoa-getinfo/cocoa_analysis_holiday.py", line 14, in main_process
    cocoa_fetch.fetch_image()
  File "/home/pi/Documents/Github/cocoa-getinfo/sub_sys/cocoa_fetch.py", line 44, in fetch_image
    img_decode = base64.b64decode(imgcode_fit.encode())
  File "/usr/local/lib/python3.7/base64.py", line 87, in b64decode

    return binascii.a2b_base64(s)
binascii.Error: Incorrect padding

1624867212943
Traceback (most recent call last):
  File "/home/pi/Documents/Github/cocoa-getinfo/cocoa_analysis_holiday.py", line 26, in <module>

    main_process()
  File "/home/pi/Documents/Github/cocoa-getinfo/cocoa_analysis_holiday.py", line 14, in main_process
    cocoa_fetch.fetch_image()
  File "/home/pi/Documents/Github/cocoa-getinfo/sub_sys/cocoa_fetch.py", line 44, in fetch_image
    img_decode = base64.b64decode(imgcode_fit.encode())
  File "/usr/local/lib/python3.7/base64.py", line 87, in b64decode

    return binascii.a2b_base64(s)
binascii.Error: Incorrect padding

1624953612620
Traceback (most recent call last):
  File "/home/pi/Documents/Github/cocoa-getinfo/cocoa_analysis_holiday.py", line 26, in <module>

    main_process()
  File "/home/pi/Documents/Github/cocoa-getinfo/cocoa_analysis_holiday.py", line 14, in main_process
    cocoa_fetch.fetch_image()
  File "/home/pi/Documents/Github/cocoa-getinfo/sub_sys/cocoa_fetch.py", line 44, in fetch_image
    img_decode = base64.b64decode(imgcode_fit.encode())
  File "/usr/local/lib/python3.7/base64.py", line 87, in b64decode

    return binascii.a2b_base64(s)
binascii.Error: Incorrect padding

1625040012485
Traceback (most recent call last):
  File "/home/pi/Documents/Github/cocoa-getinfo/cocoa_analysis_holiday.py", line 26, in <module>

    main_process()
  File "/home/pi/Documents/Github/cocoa-getinfo/cocoa_analysis_holiday.py", line 14, in main_process
    cocoa_fetch.fetch_image()
  File "/home/pi/Documents/Github/cocoa-getinfo/sub_sys/cocoa_fetch.py", line 44, in fetch_image
    img_decode = base64.b64decode(imgcode_fit.encode())
  File "/usr/local/lib/python3.7/base64.py", line 87, in b64decode

    return binascii.a2b_base64(s)
binascii.Error: Incorrect padding

1625126413163
Traceback (most recent call last):
  File "/home/pi/Documents/Github/cocoa-getinfo/cocoa_analysis_holiday.py", line 26, in <module>

    main_process()
  File "/home/pi/Documents/Github/cocoa-getinfo/cocoa_analysis_holiday.py", line 14, in main_process
    cocoa_fetch.fetch_image()
  File "/home/pi/Documents/Github/cocoa-getinfo/sub_sys/cocoa_fetch.py", line 44, in fetch_image
    img_decode = base64.b64decode(imgcode_fit.encode())
  File "/usr/local/lib/python3.7/base64.py", line 87, in b64decode

    return binascii.a2b_base64(s)
binascii.Error: Incorrect padding

1625140977793
Traceback (most recent call last):
  File "/home/pi/Documents/Github/cocoa-getinfo/cocoa_analysis_holiday.py", line 26, in <module>

    main_process()
  File "/home/pi/Documents/Github/cocoa-getinfo/cocoa_analysis_holiday.py", line 14, in main_process
    cocoa_fetch.fetch_image()
  File "/home/pi/Documents/Github/cocoa-getinfo/sub_sys/cocoa_fetch.py", line 44, in fetch_image
    img_decode = base64.b64decode(imgcode_fit.encode())
  File "/usr/local/lib/python3.7/base64.py", line 87, in b64decode
    return binascii.a2b_base64(s)
binascii.Error: Incorrect padding

1625141534409
Traceback (most recent call last):
  File "/home/pi/Documents/Github/cocoa-getinfo/cocoa_analysis_holiday.py", line 2, in <module>

    from sub_sys import cocoa_fetch
  File "/home/pi/Documents/Github/cocoa-getinfo/sub_sys/cocoa_fetch.py", line 48
    if('base64' in img_select){
                              ^
SyntaxError: invalid syntax

1625141707648
Traceback (most recent call last):
  File "/home/pi/Documents/Github/cocoa-getinfo/cocoa_analysis_holiday.py", line 2, in <module>

    from sub_sys import cocoa_fetch
  File "/home/pi/Documents/Github/cocoa-getinfo/sub_sys/cocoa_fetch.py", line 55
    elif '.png' in img_select:
                             ^
IndentationError: unindent does not match any outer indentation level

1625141780090
1625212813085
1625299212807
1625385612566
1625472013038
1625558412562
1625644813211
1625731212709
1625817613368
Traceback (most recent call last):
  File "/home/pi/Documents/Github/cocoa-getinfo/webupdate_notify.py", line 85, in <module>
    cocoa_analysis.main_process()
  File "/home/pi/Documents/Github/cocoa-getinfo/cocoa_analysis.py", line 23, in main_process
    cocoa_wordsearch_datapush.search_and_push(1)
  File "/home/pi/Documents/Github/cocoa-getinfo/sub_sys/cocoa_wordsearch_datapush.py", line 189, in search_and_push
    ffound2 = int(re.sub("\\D", "", found2))
ValueError: invalid literal for int() with base 10: ''

1625833763491
Traceback (most recent call last):
  File "/home/pi/Documents/Github/cocoa-getinfo/webupdate_notify.py", line 85, in <module>

    cocoa_analysis.main_process()
  File "/home/pi/Documents/Github/cocoa-getinfo/cocoa_analysis.py", line 23, in main_process
    cocoa_wordsearch_datapush.search_and_push(1)
  File "/home/pi/Documents/Github/cocoa-getinfo/sub_sys/cocoa_wordsearch_datapush.py", line 189, in search_and_push
    ffound2 = int(re.sub("\\D", "", found2))
ValueError: invalid literal for int() with base 10: ''

1625834028568
1625904013161
1625990413138
1626314625729
1626336000058
1626422412080
Traceback (most recent call last):
  File "/home/pi/Documents/Github/cocoa-getinfo/webupdate_notify.py", line 85, in <module>

    cocoa_analysis.main_process()
  File "/home/pi/Documents/Github/cocoa-getinfo/cocoa_analysis.py", line 47, in main_process
    cocoa_rolling_plot.graph_dl_rol(df[0],df[1])
  File "/home/pi/Documents/Github/cocoa-getinfo/sub_sys/cocoa_rolling_plot.py", line 206, in graph_dl_rol
    spline = spline_interp(df_copy['Update'][s11mask],df_copy['Downlowd incremental(×10,000)'][s11mask])
  File "/home/pi/Documents/Github/cocoa-getinfo/sub_sys/cocoa_rolling_plot.py", line 51, in spline_interp
    f = interpolate.Akima1DInterpolator(t_uni,y)
  File "/home/pi/.local/lib/python3.7/site-packages/scipy/interpolate/_cubic.py", line 415, in __init__

    x, dx, y, axis, _ = prepare_input(x, y, axis)
  File "/home/pi/.local/lib/python3.7/site-packages/scipy/interpolate/_cubic.py", line 61, in prepare_input
    raise ValueError("`x` must be strictly increasing sequence.")
ValueError: `x` must be strictly increasing sequence.

1626508812833
1626596200983
1626681612559
1626768012889
1626854413025
1626940812394
1627027212406
1627113613116
1627200012600
1627286412994
1627372812825
1627459212811
1627545612871
1627632012763
/home/pi/.local/lib/python3.7/site-packages/PIL/Image.py:963: UserWarning: Palette images with Transparency expressed in bytes should be converted to RGBA images
  "Palette images with Transparency expressed in bytes should be "

Traceback (most recent call last):
  File "/home/pi/Documents/Github/cocoa-getinfo/webupdate_notify.py", line 85, in <module>

    cocoa_analysis.main_process()
  File "/home/pi/Documents/Github/cocoa-getinfo/cocoa_analysis.py", line 40, in main_process

    cocoa_create_plot.graph_date(df[0])
  File "/home/pi/Documents/Github/cocoa-getinfo/sub_sys/cocoa_create_plot.py", line 175, in graph_date

    spline = spline_interp(df_copy['Update'][s11mask],df_copy['Download(×10,000)'][s11mask])
  File "/home/pi/Documents/Github/cocoa-getinfo/sub_sys/cocoa_create_plot.py", line 46, in spline_interp

    f = interpolate.Akima1DInterpolator(t_uni,y)
  File "/home/pi/.local/lib/python3.7/site-packages/scipy/interpolate/_cubic.py", line 415, in __init__

    x, dx, y, axis, _ = prepare_input(x, y, axis)
  File "/home/pi/.local/lib/python3.7/site-packages/scipy/interpolate/_cubic.py", line 61, in prepare_input
    raise ValueError("`x` must be strictly increasing sequence.")
ValueError: `x` must be strictly increasing sequence.

1627640627351
1627640736044
Traceback (most recent call last):
  File "/home/pi/Documents/Github/cocoa-getinfo/cocoa_analysis_skip.py", line 63, in <module>

    main_process()
  File "/home/pi/Documents/Github/cocoa-getinfo/cocoa_analysis_skip.py", line 40, in main_process
    cocoa_create_plot.graph_date(df[0])
  File "/home/pi/Documents/Github/cocoa-getinfo/sub_sys/cocoa_create_plot.py", line 175, in graph_date
    spline = spline_interp(df_copy['Update'][s11mask],df_copy['Download(×10,000)'][s11mask])
  File "/home/pi/Documents/Github/cocoa-getinfo/sub_sys/cocoa_create_plot.py", line 46, in spline_interp
    f = interpolate.Akima1DInterpolator(t_uni,y)
  File "/home/pi/.local/lib/python3.7/site-packages/scipy/interpolate/_cubic.py", line 415, in __init__

    x, dx, y, axis, _ = prepare_input(x, y, axis)
  File "/home/pi/.local/lib/python3.7/site-packages/scipy/interpolate/_cubic.py", line 61, in prepare_input

    raise ValueError("`x` must be strictly increasing sequence.")
ValueError: `x` must be strictly increasing sequence.

1627641791974
Traceback (most recent call last):
  File "/home/pi/Documents/Github/cocoa-getinfo/cocoa_analysis_skip.py", line 63, in <module>

    main_process()
  File "/home/pi/Documents/Github/cocoa-getinfo/cocoa_analysis_skip.py", line 40, in main_process
    cocoa_create_plot.graph_date(df[0])
  File "/home/pi/Documents/Github/cocoa-getinfo/sub_sys/cocoa_create_plot.py", line 175, in graph_date
    spline = spline_interp(df_copy['Update'][s11mask],df_copy['Download(×10,000)'][s11mask])
  File "/home/pi/Documents/Github/cocoa-getinfo/sub_sys/cocoa_create_plot.py", line 46, in spline_interp
    f = interpolate.Akima1DInterpolator(t_uni,y)
  File "/home/pi/.local/lib/python3.7/site-packages/scipy/interpolate/_cubic.py", line 415, in __init__

    x, dx, y, axis, _ = prepare_input(x, y, axis)

  File "/home/pi/.local/lib/python3.7/site-packages/scipy/interpolate/_cubic.py", line 61, in prepare_input
    raise ValueError("`x` must be strictly increasing sequence.")
ValueError: `x` must be strictly increasing sequence.

1627641885923
1627718412961
1627804812316
1627891212441
Traceback (most recent call last):
  File "/home/pi/Documents/Github/cocoa-getinfo/cocoa_analysis_holiday.py", line 26, in <module>

    main_process()
  File "/home/pi/Documents/Github/cocoa-getinfo/cocoa_analysis_holiday.py", line 20, in main_process
    cocoa_wordsearch_datapush.search_and_push(0)
  File "/home/pi/Documents/Github/cocoa-getinfo/sub_sys/cocoa_wordsearch_datapush.py", line 175, in search_and_push
    ws.append_row(datas, value_input_option='USER_ENTERED')
  File "/home/pi/.local/lib/python3.7/site-packages/gspread/models.py", line 1469, in append_row

    table_range=table_range,
  File "/home/pi/.local/lib/python3.7/site-packages/gspread/models.py", line 1507, in append_rows

    return self.spreadsheet.values_append(range_label, params, body)
  File "/home/pi/.local/lib/python3.7/site-packages/gspread/models.py", line 165, in values_append
    r = self.client.request('post', url, params=params, json=body)
  File "/home/pi/.local/lib/python3.7/site-packages/gspread/client.py", line 76, in request
    raise APIError(response)
gspread.exceptions.APIError: {'code': 403, 'message': 'The caller does not have permission', 'status': 'PERMISSION_DENIED'}

1627977612229
Traceback (most recent call last):
  File "/home/pi/Documents/Github/cocoa-getinfo/cocoa_analysis_holiday.py", line 26, in <module>

    main_process()
  File "/home/pi/Documents/Github/cocoa-getinfo/cocoa_analysis_holiday.py", line 20, in main_process
    cocoa_wordsearch_datapush.search_and_push(0)
  File "/home/pi/Documents/Github/cocoa-getinfo/sub_sys/cocoa_wordsearch_datapush.py", line 175, in search_and_push
    ws.append_row(datas, value_input_option='USER_ENTERED')
  File "/home/pi/.local/lib/python3.7/site-packages/gspread/models.py", line 1469, in append_row

    table_range=table_range,
  File "/home/pi/.local/lib/python3.7/site-packages/gspread/models.py", line 1507, in append_rows

    return self.spreadsheet.values_append(range_label, params, body)
  File "/home/pi/.local/lib/python3.7/site-packages/gspread/models.py", line 165, in values_append
    r = self.client.request('post', url, params=params, json=body)
  File "/home/pi/.local/lib/python3.7/site-packages/gspread/client.py", line 76, in request
    raise APIError(response)
gspread.exceptions.APIError: {'code': 403, 'message': 'The caller does not have permission', 'status': 'PERMISSION_DENIED'}

1628064012715
Traceback (most recent call last):
  File "/home/pi/Documents/Github/cocoa-getinfo/cocoa_analysis_holiday.py", line 26, in <module>

    main_process()
  File "/home/pi/Documents/Github/cocoa-getinfo/cocoa_analysis_holiday.py", line 20, in main_process
    cocoa_wordsearch_datapush.search_and_push(0)
  File "/home/pi/Documents/Github/cocoa-getinfo/sub_sys/cocoa_wordsearch_datapush.py", line 175, in search_and_push
    ws.append_row(datas, value_input_option='USER_ENTERED')
  File "/home/pi/.local/lib/python3.7/site-packages/gspread/models.py", line 1469, in append_row

    table_range=table_range,
  File "/home/pi/.local/lib/python3.7/site-packages/gspread/models.py", line 1507, in append_rows

    return self.spreadsheet.values_append(range_label, params, body)
  File "/home/pi/.local/lib/python3.7/site-packages/gspread/models.py", line 165, in values_append
    r = self.client.request('post', url, params=params, json=body)
  File "/home/pi/.local/lib/python3.7/site-packages/gspread/client.py", line 76, in request
    raise APIError(response)
gspread.exceptions.APIError: {'code': 403, 'message': 'The caller does not have permission', 'status': 'PERMISSION_DENIED'}

1628150412735
Traceback (most recent call last):
  File "/home/pi/Documents/Github/cocoa-getinfo/cocoa_analysis_holiday.py", line 26, in <module>
    main_process()
  File "/home/pi/Documents/Github/cocoa-getinfo/cocoa_analysis_holiday.py", line 20, in main_process
    cocoa_wordsearch_datapush.search_and_push(0)
  File "/home/pi/Documents/Github/cocoa-getinfo/sub_sys/cocoa_wordsearch_datapush.py", line 175, in search_and_push

    ws.append_row(datas, value_input_option='USER_ENTERED')
  File "/home/pi/.local/lib/python3.7/site-packages/gspread/models.py", line 1469, in append_row

    table_range=table_range,
  File "/home/pi/.local/lib/python3.7/site-packages/gspread/models.py", line 1507, in append_rows

    return self.spreadsheet.values_append(range_label, params, body)
  File "/home/pi/.local/lib/python3.7/site-packages/gspread/models.py", line 165, in values_append
    r = self.client.request('post', url, params=params, json=body)
  File "/home/pi/.local/lib/python3.7/site-packages/gspread/client.py", line 76, in request
    raise APIError(response)
gspread.exceptions.APIError: {'code': 403, 'message': 'The caller does not have permission', 'status': 'PERMISSION_DENIED'}

1628236812689
Traceback (most recent call last):
  File "/home/pi/Documents/Github/cocoa-getinfo/webupdate_notify.py", line 85, in <module>

    cocoa_analysis.main_process()
  File "/home/pi/Documents/Github/cocoa-getinfo/cocoa_analysis.py", line 47, in main_process
    cocoa_rolling_plot.graph_dl_rol(df[0],df[1])
  File "/home/pi/Documents/Github/cocoa-getinfo/sub_sys/cocoa_rolling_plot.py", line 206, in graph_dl_rol

    spline = spline_interp(df_copy['Update'][s11mask],df_copy['Downlowd incremental(×10,000)'][s11mask])
  File "/home/pi/Documents/Github/cocoa-getinfo/sub_sys/cocoa_rolling_plot.py", line 51, in spline_interp
    f = interpolate.Akima1DInterpolator(t_uni,y)
  File "/home/pi/.local/lib/python3.7/site-packages/scipy/interpolate/_cubic.py", line 415, in __init__

    x, dx, y, axis, _ = prepare_input(x, y, axis)
  File "/home/pi/.local/lib/python3.7/site-packages/scipy/interpolate/_cubic.py", line 61, in prepare_input
    raise ValueError("`x` must be strictly increasing sequence.")
ValueError: `x` must be strictly increasing sequence.

1628323212741
1628409612871
1628496012832
1628582412912
1628668812728
1628755212553
1628841612600
Traceback (most recent call last):
  File "/home/pi/Documents/Github/cocoa-getinfo/webupdate_notify.py", line 85, in <module>

    cocoa_analysis.main_process()
  File "/home/pi/Documents/Github/cocoa-getinfo/cocoa_analysis.py", line 23, in main_process
    cocoa_wordsearch_datapush.search_and_push(1)
  File "/home/pi/Documents/Github/cocoa-getinfo/sub_sys/cocoa_wordsearch_datapush.py", line 189, in search_and_push
    ffound2 = int(re.sub("\\D", "", found2))
ValueError: invalid literal for int() with base 10: ''

1628854957543
1628928012695
1629014412522
1629100813017
1629187213735
1629273612494
1629360012466
1629446412213
Traceback (most recent call last):
  File "/home/pi/Documents/Github/cocoa-getinfo/webupdate_notify.py", line 85, in <module>

    cocoa_analysis.main_process()
  File "/home/pi/Documents/Github/cocoa-getinfo/cocoa_analysis.py", line 23, in main_process
    cocoa_wordsearch_datapush.search_and_push(1)
  File "/home/pi/Documents/Github/cocoa-getinfo/sub_sys/cocoa_wordsearch_datapush.py", line 189, in search_and_push
    ffound2 = int(re.sub("\\D", "", found2))
ValueError: invalid literal for int() with base 10: ''

1629456243378
1629532812857
1629619212897
1629705612168
1629792012693
1629878412442
1629964813069
1630051213092
1630056893044
1630057109061
1630137613236
1630224012086
1630310412265
1630396812036
1630483212984
1630569613028
1630656013005
Traceback (most recent call last):
  File "/home/pi/Documents/Github/cocoa-getinfo/webupdate_notify.py", line 85, in <module>

    cocoa_analysis.main_process()
  File "/home/pi/Documents/Github/cocoa-getinfo/cocoa_analysis.py", line 23, in main_process
    cocoa_wordsearch_datapush.search_and_push(1)
  File "/home/pi/Documents/Github/cocoa-getinfo/sub_sys/cocoa_wordsearch_datapush.py", line 189, in search_and_push
    ffound2 = int(re.sub("\\D", "", found2))
ValueError: invalid literal for int() with base 10: ''

1630669113284
1630742413133
Traceback (most recent call last):
  File "/home/pi/Documents/Github/cocoa-getinfo/webupdate_notify.py", line 104, in <module>

    cocoa_analysis_holiday.main_process()
  File "/home/pi/Documents/Github/cocoa-getinfo/cocoa_analysis_holiday.py", line 17, in main_process
    cocoa_pyocr.py_ocr()
  File "/home/pi/Documents/Github/cocoa-getinfo/sub_sys/cocoa_pyocr.py", line 32, in py_ocr
    img_in = Image.open(file_name_dy)
  File "/home/pi/.local/lib/python3.7/site-packages/PIL/Image.py", line 2904, in open

    fp = builtins.open(filename, "rb")
FileNotFoundError: [Errno 2] No such file or directory: '/home/pi/Documents/Github/cocoa-getinfo/getIMG_pool/cocoa_info_20210904.png'

1630828813157
Traceback (most recent call last):
  File "/home/pi/Documents/Github/cocoa-getinfo/webupdate_notify.py", line 104, in <module>

    cocoa_analysis_holiday.main_process()
  File "/home/pi/Documents/Github/cocoa-getinfo/cocoa_analysis_holiday.py", line 17, in main_process
    cocoa_pyocr.py_ocr()
  File "/home/pi/Documents/Github/cocoa-getinfo/sub_sys/cocoa_pyocr.py", line 32, in py_ocr

    img_in = Image.open(file_name_dy)
  File "/home/pi/.local/lib/python3.7/site-packages/PIL/Image.py", line 2904, in open

    fp = builtins.open(filename, "rb")
FileNotFoundError: [Errno 2] No such file or directory: '/home/pi/Documents/Github/cocoa-getinfo/getIMG_pool/cocoa_info_20210905.png'

1630915212866
Traceback (most recent call last):
  File "/home/pi/Documents/Github/cocoa-getinfo/cocoa_analysis_holiday.py", line 26, in <module>

    main_process()
  File "/home/pi/Documents/Github/cocoa-getinfo/cocoa_analysis_holiday.py", line 17, in main_process
    cocoa_pyocr.py_ocr()
  File "/home/pi/Documents/Github/cocoa-getinfo/sub_sys/cocoa_pyocr.py", line 32, in py_ocr
    img_in = Image.open(file_name_dy)
  File "/home/pi/.local/lib/python3.7/site-packages/PIL/Image.py", line 2904, in open

    fp = builtins.open(filename, "rb")
FileNotFoundError: [Errno 2] No such file or directory: '/home/pi/Documents/Github/cocoa-getinfo/getIMG_pool/cocoa_info_20210906.png'

1631001612831
Traceback (most recent call last):
  File "/home/pi/Documents/Github/cocoa-getinfo/cocoa_analysis_holiday.py", line 26, in <module>

    main_process()
  File "/home/pi/Documents/Github/cocoa-getinfo/cocoa_analysis_holiday.py", line 17, in main_process
    cocoa_pyocr.py_ocr()
  File "/home/pi/Documents/Github/cocoa-getinfo/sub_sys/cocoa_pyocr.py", line 32, in py_ocr
    img_in = Image.open(file_name_dy)
  File "/home/pi/.local/lib/python3.7/site-packages/PIL/Image.py", line 2904, in open

    fp = builtins.open(filename, "rb")
FileNotFoundError: [Errno 2] No such file or directory: '/home/pi/Documents/Github/cocoa-getinfo/getIMG_pool/cocoa_info_20210907.png'

1631088012797
Traceback (most recent call last):
  File "/home/pi/Documents/Github/cocoa-getinfo/cocoa_analysis_holiday.py", line 26, in <module>

    main_process()
  File "/home/pi/Documents/Github/cocoa-getinfo/cocoa_analysis_holiday.py", line 14, in main_process
    cocoa_fetch.fetch_image()
  File "/home/pi/Documents/Github/cocoa-getinfo/sub_sys/cocoa_fetch.py", line 41, in fetch_image
    img_select = img_select['src']
TypeError: 'NoneType' object is not subscriptable

1631174412529
Traceback (most recent call last):
  File "/home/pi/Documents/Github/cocoa-getinfo/cocoa_analysis_holiday.py", line 26, in <module>

    main_process()
  File "/home/pi/Documents/Github/cocoa-getinfo/cocoa_analysis_holiday.py", line 14, in main_process
    cocoa_fetch.fetch_image()
  File "/home/pi/Documents/Github/cocoa-getinfo/sub_sys/cocoa_fetch.py", line 41, in fetch_image
    img_select = img_select['src']
TypeError: 'NoneType' object is not subscriptable

1631260812473
Traceback (most recent call last):
  File "/home/pi/Documents/Github/cocoa-getinfo/webupdate_notify.py", line 85, in <module>

    cocoa_analysis.main_process()
  File "/home/pi/Documents/Github/cocoa-getinfo/cocoa_analysis.py", line 17, in main_process
    cocoa_fetch.fetch_image()
  File "/home/pi/Documents/Github/cocoa-getinfo/sub_sys/cocoa_fetch.py", line 41, in fetch_image

    img_select = img_select['src']
TypeError: 'NoneType' object is not subscriptable

1631281632119
1631347212534
Traceback (most recent call last):
  File "/home/pi/Documents/Github/cocoa-getinfo/webupdate_notify.py", line 104, in <module>

    cocoa_analysis_holiday.main_process()
  File "/home/pi/Documents/Github/cocoa-getinfo/cocoa_analysis_holiday.py", line 14, in main_process
    cocoa_fetch.fetch_image()
  File "/home/pi/Documents/Github/cocoa-getinfo/sub_sys/cocoa_fetch.py", line 41, in fetch_image

    img_select = img_select['src']
TypeError: 'NoneType' object is not subscriptable

1631433612426
Traceback (most recent call last):
  File "/home/pi/Documents/Github/cocoa-getinfo/webupdate_notify.py", line 104, in <module>

    cocoa_analysis_holiday.main_process()
  File "/home/pi/Documents/Github/cocoa-getinfo/cocoa_analysis_holiday.py", line 14, in main_process
    cocoa_fetch.fetch_image()
  File "/home/pi/Documents/Github/cocoa-getinfo/sub_sys/cocoa_fetch.py", line 41, in fetch_image

    img_select = img_select['src']
TypeError: 'NoneType' object is not subscriptable

1631520012549
Traceback (most recent call last):
  File "/home/pi/Documents/Github/cocoa-getinfo/cocoa_analysis_holiday.py", line 26, in <module>

    main_process()
  File "/home/pi/Documents/Github/cocoa-getinfo/cocoa_analysis_holiday.py", line 14, in main_process
    cocoa_fetch.fetch_image()
  File "/home/pi/Documents/Github/cocoa-getinfo/sub_sys/cocoa_fetch.py", line 41, in fetch_image
    img_select = img_select['src']
TypeError: 'NoneType' object is not subscriptable

1631606412222
Traceback (most recent call last):
  File "/home/pi/Documents/Github/cocoa-getinfo/cocoa_analysis_holiday.py", line 26, in <module>

    main_process()
  File "/home/pi/Documents/Github/cocoa-getinfo/cocoa_analysis_holiday.py", line 14, in main_process
    cocoa_fetch.fetch_image()
  File "/home/pi/Documents/Github/cocoa-getinfo/sub_sys/cocoa_fetch.py", line 41, in fetch_image
    img_select = img_select['src']
TypeError: 'NoneType' object is not subscriptable

1631692813117
Traceback (most recent call last):
  File "/home/pi/Documents/Github/cocoa-getinfo/cocoa_analysis_holiday.py", line 26, in <module>

    main_process()
  File "/home/pi/Documents/Github/cocoa-getinfo/cocoa_analysis_holiday.py", line 14, in main_process
    cocoa_fetch.fetch_image()
  File "/home/pi/Documents/Github/cocoa-getinfo/sub_sys/cocoa_fetch.py", line 41, in fetch_image
    img_select = img_select['src']
TypeError: 'NoneType' object is not subscriptable

1631779213172
Traceback (most recent call last):
  File "/home/pi/Documents/Github/cocoa-getinfo/cocoa_analysis_holiday.py", line 26, in <module>

    main_process()
  File "/home/pi/Documents/Github/cocoa-getinfo/cocoa_analysis_holiday.py", line 14, in main_process
    cocoa_fetch.fetch_image()
  File "/home/pi/Documents/Github/cocoa-getinfo/sub_sys/cocoa_fetch.py", line 41, in fetch_image
    img_select = img_select['src']
TypeError: 'NoneType' object is not subscriptable

1631865613267
Traceback (most recent call last):
  File "/home/pi/Documents/Github/cocoa-getinfo/webupdate_notify.py", line 85, in <module>

    cocoa_analysis.main_process()
  File "/home/pi/Documents/Github/cocoa-getinfo/cocoa_analysis.py", line 17, in main_process
    cocoa_fetch.fetch_image()
  File "/home/pi/Documents/Github/cocoa-getinfo/sub_sys/cocoa_fetch.py", line 41, in fetch_image
    img_select = img_select['src']
TypeError: 'NoneType' object is not subscriptable

1631952012134
Traceback (most recent call last):
  File "/home/pi/Documents/Github/cocoa-getinfo/webupdate_notify.py", line 104, in <module>

    cocoa_analysis_holiday.main_process()
  File "/home/pi/Documents/Github/cocoa-getinfo/cocoa_analysis_holiday.py", line 14, in main_process
    cocoa_fetch.fetch_image()
  File "/home/pi/Documents/Github/cocoa-getinfo/sub_sys/cocoa_fetch.py", line 41, in fetch_image

    img_select = img_select['src']
TypeError: 'NoneType' object is not subscriptable

1632038413083
Traceback (most recent call last):
  File "/home/pi/Documents/Github/cocoa-getinfo/webupdate_notify.py", line 104, in <module>
    cocoa_analysis_holiday.main_process()
  File "/home/pi/Documents/Github/cocoa-getinfo/cocoa_analysis_holiday.py", line 14, in main_process

    cocoa_fetch.fetch_image()
  File "/home/pi/Documents/Github/cocoa-getinfo/sub_sys/cocoa_fetch.py", line 41, in fetch_image
    img_select = img_select['src']
TypeError: 'NoneType' object is not subscriptable

1632124813217
Traceback (most recent call last):
  File "/home/pi/Documents/Github/cocoa-getinfo/cocoa_analysis_holiday.py", line 26, in <module>
    main_process()
  File "/home/pi/Documents/Github/cocoa-getinfo/cocoa_analysis_holiday.py", line 14, in main_process
    cocoa_fetch.fetch_image()
  File "/home/pi/Documents/Github/cocoa-getinfo/sub_sys/cocoa_fetch.py", line 41, in fetch_image

    img_select = img_select['src']
TypeError: 'NoneType' object is not subscriptable

1632211212975
Traceback (most recent call last):
  File "/home/pi/Documents/Github/cocoa-getinfo/cocoa_analysis_holiday.py", line 26, in <module>

    main_process()
  File "/home/pi/Documents/Github/cocoa-getinfo/cocoa_analysis_holiday.py", line 14, in main_process
    cocoa_fetch.fetch_image()
  File "/home/pi/Documents/Github/cocoa-getinfo/sub_sys/cocoa_fetch.py", line 41, in fetch_image
    img_select = img_select['src']
TypeError: 'NoneType' object is not subscriptable

1632297612901
Traceback (most recent call last):
  File "/home/pi/Documents/Github/cocoa-getinfo/cocoa_analysis_holiday.py", line 26, in <module>

    main_process()
  File "/home/pi/Documents/Github/cocoa-getinfo/cocoa_analysis_holiday.py", line 14, in main_process
    cocoa_fetch.fetch_image()
  File "/home/pi/Documents/Github/cocoa-getinfo/sub_sys/cocoa_fetch.py", line 41, in fetch_image
    img_select = img_select['src']
TypeError: 'NoneType' object is not subscriptable

1632384012913
Traceback (most recent call last):
  File "/home/pi/Documents/Github/cocoa-getinfo/cocoa_analysis_holiday.py", line 26, in <module>

    main_process()
  File "/home/pi/Documents/Github/cocoa-getinfo/cocoa_analysis_holiday.py", line 14, in main_process
    cocoa_fetch.fetch_image()
  File "/home/pi/Documents/Github/cocoa-getinfo/sub_sys/cocoa_fetch.py", line 41, in fetch_image
    img_select = img_select['src']
TypeError: 'NoneType' object is not subscriptable

1632470412882
Traceback (most recent call last):
  File "/home/pi/Documents/Github/cocoa-getinfo/webupdate_notify.py", line 85, in <module>

    cocoa_analysis.main_process()
  File "/home/pi/Documents/Github/cocoa-getinfo/cocoa_analysis.py", line 17, in main_process
    cocoa_fetch.fetch_image()
  File "/home/pi/Documents/Github/cocoa-getinfo/sub_sys/cocoa_fetch.py", line 41, in fetch_image

    img_select = img_select['src']
TypeError: 'NoneType' object is not subscriptable

1632486852140
1632556813615
Traceback (most recent call last):
  File "/home/pi/Documents/Github/cocoa-getinfo/webupdate_notify.py", line 104, in <module>

    cocoa_analysis_holiday.main_process()
  File "/home/pi/Documents/Github/cocoa-getinfo/cocoa_analysis_holiday.py", line 14, in main_process
    cocoa_fetch.fetch_image()
  File "/home/pi/Documents/Github/cocoa-getinfo/sub_sys/cocoa_fetch.py", line 41, in fetch_image

    img_select = img_select['src']
TypeError: 'NoneType' object is not subscriptable

1632643212590
Traceback (most recent call last):
  File "/home/pi/Documents/Github/cocoa-getinfo/webupdate_notify.py", line 104, in <module>

    cocoa_analysis_holiday.main_process()
  File "/home/pi/Documents/Github/cocoa-getinfo/cocoa_analysis_holiday.py", line 14, in main_process
    cocoa_fetch.fetch_image()
  File "/home/pi/Documents/Github/cocoa-getinfo/sub_sys/cocoa_fetch.py", line 41, in fetch_image

    img_select = img_select['src']
TypeError: 'NoneType' object is not subscriptable

1632729612311
Traceback (most recent call last):
  File "/home/pi/Documents/Github/cocoa-getinfo/cocoa_analysis_holiday.py", line 26, in <module>

    main_process()
  File "/home/pi/Documents/Github/cocoa-getinfo/cocoa_analysis_holiday.py", line 14, in main_process
    cocoa_fetch.fetch_image()
  File "/home/pi/Documents/Github/cocoa-getinfo/sub_sys/cocoa_fetch.py", line 41, in fetch_image
    img_select = img_select['src']
TypeError: 'NoneType' object is not subscriptable

1632816012065
Traceback (most recent call last):
  File "/home/pi/Documents/Github/cocoa-getinfo/cocoa_analysis_holiday.py", line 26, in <module>

    main_process()
  File "/home/pi/Documents/Github/cocoa-getinfo/cocoa_analysis_holiday.py", line 14, in main_process
    cocoa_fetch.fetch_image()
  File "/home/pi/Documents/Github/cocoa-getinfo/sub_sys/cocoa_fetch.py", line 41, in fetch_image
    img_select = img_select['src']
TypeError: 'NoneType' object is not subscriptable

1632902412929
Traceback (most recent call last):
  File "/home/pi/Documents/Github/cocoa-getinfo/cocoa_analysis_holiday.py", line 26, in <module>

    main_process()
  File "/home/pi/Documents/Github/cocoa-getinfo/cocoa_analysis_holiday.py", line 14, in main_process
    cocoa_fetch.fetch_image()
  File "/home/pi/Documents/Github/cocoa-getinfo/sub_sys/cocoa_fetch.py", line 41, in fetch_image
    img_select = img_select['src']
TypeError: 'NoneType' object is not subscriptable

1632988812847
Traceback (most recent call last):
  File "/home/pi/Documents/Github/cocoa-getinfo/cocoa_analysis_holiday.py", line 26, in <module>

    main_process()
  File "/home/pi/Documents/Github/cocoa-getinfo/cocoa_analysis_holiday.py", line 14, in main_process
    cocoa_fetch.fetch_image()
  File "/home/pi/Documents/Github/cocoa-getinfo/sub_sys/cocoa_fetch.py", line 41, in fetch_image
    img_select = img_select['src']
TypeError: 'NoneType' object is not subscriptable

1633075212681
Traceback (most recent call last):
  File "/home/pi/Documents/Github/cocoa-getinfo/webupdate_notify.py", line 85, in <module>

    cocoa_analysis.main_process()
  File "/home/pi/Documents/Github/cocoa-getinfo/cocoa_analysis.py", line 17, in main_process
    cocoa_fetch.fetch_image()
  File "/home/pi/Documents/Github/cocoa-getinfo/sub_sys/cocoa_fetch.py", line 41, in fetch_image

    img_select = img_select['src']
TypeError: 'NoneType' object is not subscriptable

1633161612953
Traceback (most recent call last):
  File "/home/pi/Documents/Github/cocoa-getinfo/webupdate_notify.py", line 104, in <module>

    cocoa_analysis_holiday.main_process()
  File "/home/pi/Documents/Github/cocoa-getinfo/cocoa_analysis_holiday.py", line 14, in main_process
    cocoa_fetch.fetch_image()
  File "/home/pi/Documents/Github/cocoa-getinfo/sub_sys/cocoa_fetch.py", line 41, in fetch_image

    img_select = img_select['src']
TypeError: 'NoneType' object is not subscriptable

1633248012866
Traceback (most recent call last):
  File "/home/pi/Documents/Github/cocoa-getinfo/webupdate_notify.py", line 104, in <module>

    cocoa_analysis_holiday.main_process()
  File "/home/pi/Documents/Github/cocoa-getinfo/cocoa_analysis_holiday.py", line 14, in main_process
    cocoa_fetch.fetch_image()
  File "/home/pi/Documents/Github/cocoa-getinfo/sub_sys/cocoa_fetch.py", line 41, in fetch_image

    img_select = img_select['src']
TypeError: 'NoneType' object is not subscriptable

1633334412772
Traceback (most recent call last):
  File "/home/pi/Documents/Github/cocoa-getinfo/cocoa_analysis_holiday.py", line 26, in <module>

    main_process()
  File "/home/pi/Documents/Github/cocoa-getinfo/cocoa_analysis_holiday.py", line 14, in main_process
    cocoa_fetch.fetch_image()
  File "/home/pi/Documents/Github/cocoa-getinfo/sub_sys/cocoa_fetch.py", line 41, in fetch_image
    img_select = img_select['src']
TypeError: 'NoneType' object is not subscriptable

1633420813361
1633507212795
1633593612988
1633680012172
1633695299397
1633766412626
Traceback (most recent call last):
  File "/home/pi/Documents/Github/cocoa-getinfo/webupdate_notify.py", line 104, in <module>
    cocoa_analysis_holiday.main_process()

  File "/home/pi/Documents/Github/cocoa-getinfo/cocoa_analysis_holiday.py", line 20, in main_process
    cocoa_wordsearch_datapush.search_and_push(0)
  File "/home/pi/Documents/Github/cocoa-getinfo/sub_sys/cocoa_wordsearch_datapush.py", line 69, in search_and_push

    f1 = str(f[0])
IndexError: list index out of range

1633852813160
Traceback (most recent call last):
  File "/home/pi/Documents/Github/cocoa-getinfo/webupdate_notify.py", line 104, in <module>
    cocoa_analysis_holiday.main_process()
  File "/home/pi/Documents/Github/cocoa-getinfo/cocoa_analysis_holiday.py", line 20, in main_process

    cocoa_wordsearch_datapush.search_and_push(0)
  File "/home/pi/Documents/Github/cocoa-getinfo/sub_sys/cocoa_wordsearch_datapush.py", line 69, in search_and_push
    f1 = str(f[0])
IndexError: list index out of range

1633939212672
Traceback (most recent call last):
  File "/home/pi/Documents/Github/cocoa-getinfo/cocoa_analysis_holiday.py", line 26, in <module>
    main_process()
  File "/home/pi/Documents/Github/cocoa-getinfo/cocoa_analysis_holiday.py", line 20, in main_process
    cocoa_wordsearch_datapush.search_and_push(0)
  File "/home/pi/Documents/Github/cocoa-getinfo/sub_sys/cocoa_wordsearch_datapush.py", line 69, in search_and_push

    f1 = str(f[0])
IndexError: list index out of range

1634025612998
Traceback (most recent call last):
  File "/home/pi/Documents/Github/cocoa-getinfo/cocoa_analysis_holiday.py", line 26, in <module>
    main_process()
  File "/home/pi/Documents/Github/cocoa-getinfo/cocoa_analysis_holiday.py", line 20, in main_process
    cocoa_wordsearch_datapush.search_and_push(0)
  File "/home/pi/Documents/Github/cocoa-getinfo/sub_sys/cocoa_wordsearch_datapush.py", line 69, in search_and_push

    f1 = str(f[0])
IndexError: list index out of range

1634112013428
Traceback (most recent call last):
  File "/home/pi/Documents/Github/cocoa-getinfo/cocoa_analysis_holiday.py", line 26, in <module>
    main_process()
  File "/home/pi/Documents/Github/cocoa-getinfo/cocoa_analysis_holiday.py", line 20, in main_process
    cocoa_wordsearch_datapush.search_and_push(0)
  File "/home/pi/Documents/Github/cocoa-getinfo/sub_sys/cocoa_wordsearch_datapush.py", line 69, in search_and_push

    f1 = str(f[0])
IndexError: list index out of range

1634198412289
Traceback (most recent call last):
  File "/home/pi/Documents/Github/cocoa-getinfo/cocoa_analysis_holiday.py", line 26, in <module>
    main_process()
  File "/home/pi/Documents/Github/cocoa-getinfo/cocoa_analysis_holiday.py", line 20, in main_process
    cocoa_wordsearch_datapush.search_and_push(0)
  File "/home/pi/Documents/Github/cocoa-getinfo/sub_sys/cocoa_wordsearch_datapush.py", line 69, in search_and_push

    f1 = str(f[0])
IndexError: list index out of range

1634284812405
Traceback (most recent call last):
  File "/home/pi/Documents/Github/cocoa-getinfo/webupdate_notify.py", line 85, in <module>
    cocoa_analysis.main_process()
  File "/home/pi/Documents/Github/cocoa-getinfo/cocoa_analysis.py", line 23, in main_process

    cocoa_wordsearch_datapush.search_and_push(1)
  File "/home/pi/Documents/Github/cocoa-getinfo/sub_sys/cocoa_wordsearch_datapush.py", line 69, in search_and_push
    f1 = str(f[0])
IndexError: list index out of range

1634289833268
Traceback (most recent call last):
  File "/home/pi/Documents/Github/cocoa-getinfo/webupdate_notify.py", line 85, in <module>
    cocoa_analysis.main_process()
  File "/home/pi/Documents/Github/cocoa-getinfo/cocoa_analysis.py", line 17, in main_process
    cocoa_fetch.fetch_image()
  File "/home/pi/Documents/Github/cocoa-getinfo/sub_sys/cocoa_fetch.py", line 58, in fetch_image
    img_decode = base64.b64decode(imgcode_fit.encode())
NameError: name 'imgcode_fit' is not defined

1634296424959
1634371212995
Traceback (most recent call last):
  File "/home/pi/Documents/Github/cocoa-getinfo/webupdate_notify.py", line 104, in <module>
    cocoa_analysis_holiday.main_process()
  File "/home/pi/Documents/Github/cocoa-getinfo/cocoa_analysis_holiday.py", line 20, in main_process

    cocoa_wordsearch_datapush.search_and_push(0)
  File "/home/pi/Documents/Github/cocoa-getinfo/sub_sys/cocoa_wordsearch_datapush.py", line 69, in search_and_push

    f1 = str(f[0])
IndexError: list index out of range

1634457612098
Traceback (most recent call last):
  File "/home/pi/Documents/Github/cocoa-getinfo/webupdate_notify.py", line 104, in <module>
    cocoa_analysis_holiday.main_process()
  File "/home/pi/Documents/Github/cocoa-getinfo/cocoa_analysis_holiday.py", line 20, in main_process

    cocoa_wordsearch_datapush.search_and_push(0)
  File "/home/pi/Documents/Github/cocoa-getinfo/sub_sys/cocoa_wordsearch_datapush.py", line 69, in search_and_push

    f1 = str(f[0])
IndexError: list index out of range

